<sdf version='1.7'>
  <world name='default'>
    <plugin name='hello' filename='libhello.so'/>
    <light name='sun' type='directional'>
      <cast_shadows>1</cast_shadows>
      <pose>0 0 10 0 -0 0</pose>
      <diffuse>0.8 0.8 0.8 1</diffuse>
      <specular>0.2 0.2 0.2 1</specular>
      <attenuation>
        <range>1000</range>
        <constant>0.9</constant>
        <linear>0.01</linear>
        <quadratic>0.001</quadratic>
      </attenuation>
      <direction>-0.5 0.1 -0.9</direction>
    </light>
    <model name='ground_plane'>
      <static>1</static>
      <link name='link'>
        <collision name='collision'>
          <geometry>
            <plane>
              <normal>0 0 1</normal>
              <size>100 100</size>
            </plane>
          </geometry>
          <surface>
            <contact>
              <collide_bitmask>65535</collide_bitmask>
              <ode/>
            </contact>
            <friction>
              <ode>
                <mu>100</mu>
                <mu2>50</mu2>
              </ode>
              <torsional>
                <ode/>
              </torsional>
            </friction>
            <bounce/>
          </surface>
          <max_contacts>10</max_contacts>
        </collision>
        <visual name='visual'>
          <cast_shadows>0</cast_shadows>
          <geometry>
            <plane>
              <normal>0 0 1</normal>
              <size>100 100</size>
            </plane>
          </geometry>
          <material>
            <script>
              <uri>file://media/materials/scripts/gazebo.material</uri>
              <name>Gazebo/Grey</name>
            </script>
          </material>
        </visual>
        <self_collide>0</self_collide>
        <enable_wind>0</enable_wind>
        <kinematic>0</kinematic>
      </link>
    </model>
    <gravity>0 0 -9.8</gravity>
    <magnetic_field>6e-06 2.3e-05 -4.2e-05</magnetic_field>
    <atmosphere type='adiabatic'/>
    <physics name='default_physics' default='0' type='ode'>
      <max_step_size>0.001</max_step_size>
      <real_time_factor>1</real_time_factor>
      <real_time_update_rate>1000</real_time_update_rate>
    </physics>
    <scene>
      <ambient>0.4 0.4 0.4 1</ambient>
      <background>0.7 0.7 0.7 1</background>
      <shadows>1</shadows>
    </scene>
    <wind/>
    <spherical_coordinates>
      <surface_model>EARTH_WGS84</surface_model>
      <latitude_deg>0</latitude_deg>
      <longitude_deg>0</longitude_deg>
      <elevation>0</elevation>
      <heading_deg>0</heading_deg>
    </spherical_coordinates>
    <model name='robot'>
      <link name='link_0'>
        <inertial>
          <mass>1</mass>
          <inertia>
            <ixx>0.166667</ixx>
            <ixy>0</ixy>
            <ixz>0</ixz>
            <iyy>0.166667</iyy>
            <iyz>0</iyz>
            <izz>0.166667</izz>
          </inertia>
          <pose>0 0 0 0 -0 0</pose>
        </inertial>
        <pose>-1e-06 -0.010289 0 0 -0 0</pose>
        <gravity>1</gravity>
        <self_collide>0</self_collide>
        <kinematic>0</kinematic>
        <enable_wind>0</enable_wind>
        <visual name='visual'>
          <pose>0 0 0 0 -0 0</pose>
          <geometry>
            <box>
              <size>0.3 0.6 0.1</size>
            </box>
          </geometry>
          <material>
            <lighting>1</lighting>
            <script>
              <uri>file://media/materials/scripts/gazebo.material</uri>
              <name>Gazebo/Grey</name>
            </script>
            <shader type='pixel'>
              <normal_map>__default__</normal_map>
            </shader>
            <ambient>0.3 0.3 0.3 1</ambient>
            <diffuse>0.7 0.7 0.7 1</diffuse>
            <specular>0.01 0.01 0.01 1</specular>
            <emissive>0 0 0 1</emissive>
          </material>
          <transparency>0</transparency>
          <cast_shadows>1</cast_shadows>
        </visual>
        <collision name='collision'>
          <laser_retro>0</laser_retro>
          <max_contacts>10</max_contacts>
          <pose>0 0 0 0 -0 0</pose>
          <geometry>
            <box>
              <size>0.3 0.6 0.1</size>
            </box>
          </geometry>
          <surface>
            <friction>
              <ode>
                <mu>1</mu>
                <mu2>1</mu2>
                <fdir1>0 0 0</fdir1>
                <slip1>0</slip1>
                <slip2>0</slip2>
              </ode>
              <torsional>
                <coefficient>1</coefficient>
                <patch_radius>0</patch_radius>
                <surface_radius>0</surface_radius>
                <use_patch_radius>1</use_patch_radius>
                <ode>
                  <slip>0</slip>
                </ode>
              </torsional>
            </friction>
            <bounce>
              <restitution_coefficient>0</restitution_coefficient>
              <threshold>1e+06</threshold>
            </bounce>
            <contact>
              <collide_without_contact>0</collide_without_contact>
              <collide_without_contact_bitmask>1</collide_without_contact_bitmask>
              <collide_bitmask>1</collide_bitmask>
              <ode>
                <soft_cfm>0</soft_cfm>
                <soft_erp>0.2</soft_erp>
                <kp>1e+13</kp>
                <kd>1</kd>
                <max_vel>0.01</max_vel>
                <min_depth>0</min_depth>
              </ode>
              <bullet>
                <split_impulse>1</split_impulse>
                <split_impulse_penetration_threshold>-0.01</split_impulse_penetration_threshold>
                <soft_cfm>0</soft_cfm>
                <soft_erp>0.2</soft_erp>
                <kp>1e+13</kp>
                <kd>1</kd>
              </bullet>
            </contact>
          </surface>
        </collision>
      </link>
      <link name='link_1_clone_0'>
        <inertial>
          <mass>1</mass>
          <inertia>
            <ixx>0.145833</ixx>
            <ixy>0</ixy>
            <ixz>0</ixz>
            <iyy>0.145833</iyy>
            <iyz>0</iyz>
            <izz>0.125</izz>
          </inertia>
          <pose>0 0 0 0 -0 0</pose>
        </inertial>
        <pose>-0.155011 0.239711 0 1.5707 0 1.5707</pose>
        <gravity>1</gravity>
        <self_collide>0</self_collide>
        <kinematic>0</kinematic>
        <enable_wind>0</enable_wind>
        <visual name='visual'>
          <pose>0 0 0 0 -0 0</pose>
          <geometry>
            <cylinder>
              <radius>0.07</radius>
              <length>0.01</length>
            </cylinder>
          </geometry>
          <material>
            <lighting>1</lighting>
            <script>
              <uri>file://media/materials/scripts/gazebo.material</uri>
              <name>Gazebo/Grey</name>
            </script>
            <shader type='pixel'>
              <normal_map>__default__</normal_map>
            </shader>
            <ambient>0.3 0.3 0.3 1</ambient>
            <diffuse>0.7 0.7 0.7 1</diffuse>
            <specular>0.01 0.01 0.01 1</specular>
            <emissive>0 0 0 1</emissive>
          </material>
          <transparency>0</transparency>
          <cast_shadows>1</cast_shadows>
        </visual>
        <collision name='collision'>
          <laser_retro>0</laser_retro>
          <max_contacts>10</max_contacts>
          <pose>0 0 0 0 -0 0</pose>
          <geometry>
            <cylinder>
              <radius>0.07</radius>
              <length>0.01</length>
            </cylinder>
          </geometry>
          <surface>
            <friction>
              <ode>
                <mu>1</mu>
                <mu2>1</mu2>
                <fdir1>0 0 0</fdir1>
                <slip1>0</slip1>
                <slip2>0</slip2>
              </ode>
              <torsional>
                <coefficient>1</coefficient>
                <patch_radius>0</patch_radius>
                <surface_radius>0</surface_radius>
                <use_patch_radius>1</use_patch_radius>
                <ode>
                  <slip>0</slip>
                </ode>
              </torsional>
            </friction>
            <bounce>
              <restitution_coefficient>0</restitution_coefficient>
              <threshold>1e+06</threshold>
            </bounce>
            <contact>
              <collide_without_contact>0</collide_without_contact>
              <collide_without_contact_bitmask>1</collide_without_contact_bitmask>
              <collide_bitmask>1</collide_bitmask>
              <ode>
                <soft_cfm>0</soft_cfm>
                <soft_erp>0.2</soft_erp>
                <kp>1e+13</kp>
                <kd>1</kd>
                <max_vel>0.01</max_vel>
                <min_depth>0</min_depth>
              </ode>
              <bullet>
                <split_impulse>1</split_impulse>
                <split_impulse_penetration_threshold>-0.01</split_impulse_penetration_threshold>
                <soft_cfm>0</soft_cfm>
                <soft_erp>0.2</soft_erp>
                <kp>1e+13</kp>
                <kd>1</kd>
              </bullet>
            </contact>
          </surface>
        </collision>
      </link>
      <link name='link_1_clone_0_clone'>
        <inertial>
          <mass>1</mass>
          <inertia>
            <ixx>0.145833</ixx>
            <ixy>0</ixy>
            <ixz>0</ixz>
            <iyy>0.145833</iyy>
            <iyz>0</iyz>
            <izz>0.125</izz>
          </inertia>
          <pose>0 0 0 0 -0 0</pose>
        </inertial>
        <pose>0.155013 0.251154 0 1.5707 0 1.5707</pose>
        <gravity>1</gravity>
        <self_collide>0</self_collide>
        <kinematic>0</kinematic>
        <enable_wind>0</enable_wind>
        <visual name='visual'>
          <pose>0 0 0 0 -0 0</pose>
          <geometry>
            <cylinder>
              <radius>0.07</radius>
              <length>0.01</length>
            </cylinder>
          </geometry>
          <material>
            <lighting>1</lighting>
            <script>
              <uri>file://media/materials/scripts/gazebo.material</uri>
              <name>Gazebo/Grey</name>
            </script>
            <shader type='pixel'>
              <normal_map>__default__</normal_map>
            </shader>
            <ambient>0.3 0.3 0.3 1</ambient>
            <diffuse>0.7 0.7 0.7 1</diffuse>
            <specular>0.01 0.01 0.01 1</specular>
            <emissive>0 0 0 1</emissive>
          </material>
          <transparency>0</transparency>
          <cast_shadows>1</cast_shadows>
        </visual>
        <collision name='collision'>
          <laser_retro>0</laser_retro>
          <max_contacts>10</max_contacts>
          <pose>0 0 0 0 -0 0</pose>
          <geometry>
            <cylinder>
              <radius>0.07</radius>
              <length>0.01</length>
            </cylinder>
          </geometry>
          <surface>
            <friction>
              <ode>
                <mu>1</mu>
                <mu2>1</mu2>
                <fdir1>0 0 0</fdir1>
                <slip1>0</slip1>
                <slip2>0</slip2>
              </ode>
              <torsional>
                <coefficient>1</coefficient>
                <patch_radius>0</patch_radius>
                <surface_radius>0</surface_radius>
                <use_patch_radius>1</use_patch_radius>
                <ode>
                  <slip>0</slip>
                </ode>
              </torsional>
            </friction>
            <bounce>
              <restitution_coefficient>0</restitution_coefficient>
              <threshold>1e+06</threshold>
            </bounce>
            <contact>
              <collide_without_contact>0</collide_without_contact>
              <collide_without_contact_bitmask>1</collide_without_contact_bitmask>
              <collide_bitmask>1</collide_bitmask>
              <ode>
                <soft_cfm>0</soft_cfm>
                <soft_erp>0.2</soft_erp>
                <kp>1e+13</kp>
                <kd>1</kd>
                <max_vel>0.01</max_vel>
                <min_depth>0</min_depth>
              </ode>
              <bullet>
                <split_impulse>1</split_impulse>
                <split_impulse_penetration_threshold>-0.01</split_impulse_penetration_threshold>
                <soft_cfm>0</soft_cfm>
                <soft_erp>0.2</soft_erp>
                <kp>1e+13</kp>
                <kd>1</kd>
              </bullet>
            </contact>
          </surface>
        </collision>
      </link>
      <link name='link_1_clone_0_clone_0'>
        <inertial>
          <mass>1</mass>
          <inertia>
            <ixx>0.145833</ixx>
            <ixy>0</ixy>
            <ixz>0</ixz>
            <iyy>0.145833</iyy>
            <iyz>0</iyz>
            <izz>0.125</izz>
          </inertia>
          <pose>0 0 0 0 -0 0</pose>
        </inertial>
        <pose>0.155013 -0.240288 0 1.5707 0 1.5707</pose>
        <gravity>1</gravity>
        <self_collide>0</self_collide>
        <kinematic>0</kinematic>
        <enable_wind>0</enable_wind>
        <visual name='visual'>
          <pose>0 0 0 0 -0 0</pose>
          <geometry>
            <cylinder>
              <radius>0.07</radius>
              <length>0.01</length>
            </cylinder>
          </geometry>
          <material>
            <lighting>1</lighting>
            <script>
              <uri>file://media/materials/scripts/gazebo.material</uri>
              <name>Gazebo/Grey</name>
            </script>
            <shader type='pixel'>
              <normal_map>__default__</normal_map>
            </shader>
            <ambient>0.3 0.3 0.3 1</ambient>
            <diffuse>0.7 0.7 0.7 1</diffuse>
            <specular>0.01 0.01 0.01 1</specular>
            <emissive>0 0 0 1</emissive>
          </material>
          <transparency>0</transparency>
          <cast_shadows>1</cast_shadows>
        </visual>
        <collision name='collision'>
          <laser_retro>0</laser_retro>
          <max_contacts>10</max_contacts>
          <pose>0 0 0 0 -0 0</pose>
          <geometry>
            <cylinder>
              <radius>0.07</radius>
              <length>0.01</length>
            </cylinder>
          </geometry>
          <surface>
            <friction>
              <ode>
                <mu>1</mu>
                <mu2>1</mu2>
                <fdir1>0 0 0</fdir1>
                <slip1>0</slip1>
                <slip2>0</slip2>
              </ode>
              <torsional>
                <coefficient>1</coefficient>
                <patch_radius>0</patch_radius>
                <surface_radius>0</surface_radius>
                <use_patch_radius>1</use_patch_radius>
                <ode>
                  <slip>0</slip>
                </ode>
              </torsional>
            </friction>
            <bounce>
              <restitution_coefficient>0</restitution_coefficient>
              <threshold>1e+06</threshold>
            </bounce>
            <contact>
              <collide_without_contact>0</collide_without_contact>
              <collide_without_contact_bitmask>1</collide_without_contact_bitmask>
              <collide_bitmask>1</collide_bitmask>
              <ode>
                <soft_cfm>0</soft_cfm>
                <soft_erp>0.2</soft_erp>
                <kp>1e+13</kp>
                <kd>1</kd>
                <max_vel>0.01</max_vel>
                <min_depth>0</min_depth>
              </ode>
              <bullet>
                <split_impulse>1</split_impulse>
                <split_impulse_penetration_threshold>-0.01</split_impulse_penetration_threshold>
                <soft_cfm>0</soft_cfm>
                <soft_erp>0.2</soft_erp>
                <kp>1e+13</kp>
                <kd>1</kd>
              </bullet>
            </contact>
          </surface>
        </collision>
      </link>
      <link name='link_1_clone_0_clone_0_clone'>
        <inertial>
          <mass>1</mass>
          <inertia>
            <ixx>0.145833</ixx>
            <ixy>0</ixy>
            <ixz>0</ixz>
            <iyy>0.145833</iyy>
            <iyz>0</iyz>
            <izz>0.125</izz>
          </inertia>
          <pose>0 0 0 0 -0 0</pose>
        </inertial>
        <pose>-0.155014 -0.240288 0 1.5707 0 1.5707</pose>
        <gravity>1</gravity>
        <self_collide>0</self_collide>
        <kinematic>0</kinematic>
        <enable_wind>0</enable_wind>
        <visual name='visual'>
          <pose>0 0 0 0 -0 0</pose>
          <geometry>
            <cylinder>
              <radius>0.07</radius>
              <length>0.01</length>
            </cylinder>
          </geometry>
          <material>
            <lighting>1</lighting>
            <script>
              <uri>file://media/materials/scripts/gazebo.material</uri>
              <name>Gazebo/Grey</name>
            </script>
            <shader type='pixel'>
              <normal_map>__default__</normal_map>
            </shader>
            <ambient>0.3 0.3 0.3 1</ambient>
            <diffuse>0.7 0.7 0.7 1</diffuse>
            <specular>0.01 0.01 0.01 1</specular>
            <emissive>0 0 0 1</emissive>
          </material>
          <transparency>0</transparency>
          <cast_shadows>1</cast_shadows>
        </visual>
        <collision name='collision'>
          <laser_retro>0</laser_retro>
          <max_contacts>10</max_contacts>
          <pose>0 0 0 0 -0 0</pose>
          <geometry>
            <cylinder>
              <radius>0.07</radius>
              <length>0.01</length>
            </cylinder>
          </geometry>
          <surface>
            <friction>
              <ode>
                <mu>1</mu>
                <mu2>1</mu2>
                <fdir1>0 0 0</fdir1>
                <slip1>0</slip1>
                <slip2>0</slip2>
              </ode>
              <torsional>
                <coefficient>1</coefficient>
                <patch_radius>0</patch_radius>
                <surface_radius>0</surface_radius>
                <use_patch_radius>1</use_patch_radius>
                <ode>
                  <slip>0</slip>
                </ode>
              </torsional>
            </friction>
            <bounce>
              <restitution_coefficient>0</restitution_coefficient>
              <threshold>1e+06</threshold>
            </bounce>
            <contact>
              <collide_without_contact>0</collide_without_contact>
              <collide_without_contact_bitmask>1</collide_without_contact_bitmask>
              <collide_bitmask>1</collide_bitmask>
              <ode>
                <soft_cfm>0</soft_cfm>
                <soft_erp>0.2</soft_erp>
                <kp>1e+13</kp>
                <kd>1</kd>
                <max_vel>0.01</max_vel>
                <min_depth>0</min_depth>
              </ode>
              <bullet>
                <split_impulse>1</split_impulse>
                <split_impulse_penetration_threshold>-0.01</split_impulse_penetration_threshold>
                <soft_cfm>0</soft_cfm>
                <soft_erp>0.2</soft_erp>
                <kp>1e+13</kp>
                <kd>1</kd>
              </bullet>
            </contact>
          </surface>
        </collision>
      </link>
      <joint name='link_0_JOINT_2' type='revolute'>
        <parent>link_0</parent>
        <child>link_1_clone_0</child>
        <pose>0 0 0 0 -0 0</pose>
        <axis>
          <xyz>0 0 1</xyz>
          <limit>
            <lower>-1.79769e+308</lower>
            <upper>1.79769e+308</upper>
            <effort>-1</effort>
            <velocity>-1</velocity>
          </limit>
          <dynamics>
            <spring_reference>0</spring_reference>
            <spring_stiffness>0</spring_stiffness>
            <damping>0</damping>
          </dynamics>
        </axis>
        <physics>
          <ode>
            <limit>
              <cfm>0</cfm>
              <erp>0.2</erp>
            </limit>
            <suspension>
              <cfm>0</cfm>
              <erp>0.2</erp>
            </suspension>
          </ode>
        </physics>
      </joint>
      <joint name='link_0_JOINT_3' type='revolute'>
        <parent>link_0</parent>
        <child>link_1_clone_0_clone</child>
        <pose>-0.02 0 0 0 -0 0</pose>
        <axis>
          <xyz>0 0 1</xyz>
          <limit>
            <lower>-1.79769e+308</lower>
            <upper>1.79769e+308</upper>
            <effort>-1</effort>
            <velocity>-1</velocity>
          </limit>
          <dynamics>
            <spring_reference>0</spring_reference>
            <spring_stiffness>0</spring_stiffness>
            <damping>0</damping>
          </dynamics>
        </axis>
        <physics>
          <ode>
            <limit>
              <cfm>0</cfm>
              <erp>0.2</erp>
            </limit>
            <suspension>
              <cfm>0</cfm>
              <erp>0.2</erp>
            </suspension>
          </ode>
        </physics>
      </joint>
      <joint name='link_0_JOINT_4' type='revolute'>
        <parent>link_0</parent>
        <child>link_1_clone_0_clone_0</child>
        <pose>0 0 0 0 -0 0</pose>
        <axis>
          <xyz>0 0 1</xyz>
          <limit>
            <lower>-1.79769e+308</lower>
            <upper>1.79769e+308</upper>
            <effort>-1</effort>
            <velocity>-1</velocity>
          </limit>
          <dynamics>
            <spring_reference>0</spring_reference>
            <spring_stiffness>0</spring_stiffness>
            <damping>0</damping>
          </dynamics>
        </axis>
        <physics>
          <ode>
            <limit>
              <cfm>0</cfm>
              <erp>0.2</erp>
            </limit>
            <suspension>
              <cfm>0</cfm>
              <erp>0.2</erp>
            </suspension>
          </ode>
        </physics>
      </joint>
      <joint name='link_0_JOINT_5' type='revolute'>
        <parent>link_0</parent>
        <child>link_1_clone_0_clone_0_clone</child>
        <pose>0 0 0 0 -0 0</pose>
        <axis>
          <xyz>0 0 1</xyz>
          <limit>
            <lower>-1.79769e+308</lower>
            <upper>1.79769e+308</upper>
            <effort>-1</effort>
            <velocity>-1</velocity>
          </limit>
          <dynamics>
            <spring_reference>0</spring_reference>
            <spring_stiffness>0</spring_stiffness>
            <damping>0</damping>
          </dynamics>
        </axis>
        <physics>
          <ode>
            <limit>
              <cfm>0</cfm>
              <erp>0.2</erp>
            </limit>
            <suspension>
              <cfm>0</cfm>
              <erp>0.2</erp>
            </suspension>
          </ode>
        </physics>
      </joint>
      <static>0</static>
      <allow_auto_disable>1</allow_auto_disable>
      <pose>1e-06 0.010289 0.2 0 -0 0</pose>
    </model>
    <state world_name='default'>
      <sim_time>1083 888000000</sim_time>
      <real_time>33 81312043</real_time>
      <wall_time>1588009717 82113133</wall_time>
      <iterations>32995</iterations>
      <model name='ground_plane'>
        <pose>0 0 0 0 -0 0</pose>
        <scale>1 1 1</scale>
        <link name='link'>
          <pose>0 0 0 0 -0 0</pose>
          <velocity>0 0 0 0 -0 0</velocity>
          <acceleration>0 0 0 0 -0 0</acceleration>
          <wrench>0 0 0 0 -0 0</wrench>
        </link>
      </model>
      <model name='mybuilding'>
        <pose>4.15485 -0.025661 0 0 -0 0</pose>
        <scale>1 1 1</scale>
        <link name='Wall_0'>
          <pose>0.465582 1.68693 0 0 -0 0</pose>
          <velocity>0 0 0 0 -0 0</velocity>
          <acceleration>0 0 0 0 -0 0</acceleration>
          <wrench>0 0 0 0 -0 0</wrench>
        </link>
        <link name='Wall_1'>
          <pose>3.72058 0.891932 0 0 0 -0.760863</pose>
          <velocity>0 0 0 0 -0 0</velocity>
          <acceleration>0 0 0 0 -0 0</acceleration>
          <wrench>0 0 0 0 -0 0</wrench>
        </link>
        <link name='Wall_10'>
          <pose>4.30558 -2.35307 0 0 -0 3.14159</pose>
          <velocity>0 0 0 0 -0 0</velocity>
          <acceleration>0 0 0 0 -0 0</acceleration>
          <wrench>0 0 0 0 -0 0</wrench>
        </link>
        <link name='Wall_11'>
          <pose>3.25558 -1.80307 0 0 -0 1.5708</pose>
          <velocity>0 0 0 0 -0 0</velocity>
          <acceleration>0 0 0 0 -0 0</acceleration>
          <wrench>0 0 0 0 -0 0</wrench>
        </link>
        <link name='Wall_12'>
          <pose>1.49525 -1.25307 0 0 -0 3.14159</pose>
          <velocity>0 0 0 0 -0 0</velocity>
          <acceleration>0 0 0 0 -0 0</acceleration>
          <wrench>0 0 0 0 -0 0</wrench>
        </link>
        <link name='Wall_13'>
          <pose>-0.284908 -1.80307 0 0 0 -1.53474</pose>
          <velocity>0 0 0 0 -0 0</velocity>
          <acceleration>0 0 0 0 -0 0</acceleration>
          <wrench>0 0 0 0 -0 0</wrench>
        </link>
        <link name='Wall_14'>
          <pose>-1.13986 -2.37219 0 0 0 -3.11973</pose>
          <velocity>0 0 0 0 -0 0</velocity>
          <acceleration>0 0 0 0 -0 0</acceleration>
          <wrench>0 0 0 0 -0 0</wrench>
        </link>
        <link name='Wall_15'>
          <pose>-2.05454 -0.342196 0 0 -0 1.59026</pose>
          <velocity>0 0 0 0 -0 0</velocity>
          <acceleration>0 0 0 0 -0 0</acceleration>
          <wrench>0 0 0 0 -0 0</wrench>
        </link>
        <link name='Wall_2'>
          <pose>7.48058 0.096932 0 0 -0 0</pose>
          <velocity>0 0 0 0 -0 0</velocity>
          <acceleration>0 0 0 0 -0 0</acceleration>
          <wrench>0 0 0 0 -0 0</wrench>
        </link>
        <link name='Wall_3'>
          <pose>10.4056 -0.703068 0 0 0 -1.5708</pose>
          <velocity>0 0 0 0 -0 0</velocity>
          <acceleration>0 0 0 0 -0 0</acceleration>
          <wrench>0 0 0 0 -0 0</wrench>
        </link>
        <link name='Wall_4'>
          <pose>9.48058 -1.50307 0 0 -0 3.14159</pose>
          <velocity>0 0 0 0 -0 0</velocity>
          <acceleration>0 0 0 0 -0 0</acceleration>
          <wrench>0 0 0 0 -0 0</wrench>
        </link>
        <link name='Wall_5'>
          <pose>8.55558 -1.92807 0 0 0 -1.5708</pose>
          <velocity>0 0 0 0 -0 0</velocity>
          <acceleration>0 0 0 0 -0 0</acceleration>
          <wrench>0 0 0 0 -0 0</wrench>
        </link>
        <link name='Wall_6'>
          <pose>7.88058 -2.35307 0 0 -0 3.14159</pose>
          <velocity>0 0 0 0 -0 0</velocity>
          <acceleration>0 0 0 0 -0 0</acceleration>
          <wrench>0 0 0 0 -0 0</wrench>
        </link>
        <link name='Wall_7'>
          <pose>7.20558 -1.92807 0 0 -0 1.5708</pose>
          <velocity>0 0 0 0 -0 0</velocity>
          <acceleration>0 0 0 0 -0 0</acceleration>
          <wrench>0 0 0 0 -0 0</wrench>
        </link>
        <link name='Wall_8'>
          <pose>6.28058 -1.50307 0 0 -0 3.14159</pose>
          <velocity>0 0 0 0 -0 0</velocity>
          <acceleration>0 0 0 0 -0 0</acceleration>
          <wrench>0 0 0 0 -0 0</wrench>
        </link>
        <link name='Wall_9'>
          <pose>5.35558 -1.92807 0 0 0 -1.5708</pose>
          <velocity>0 0 0 0 -0 0</velocity>
          <acceleration>0 0 0 0 -0 0</acceleration>
          <wrench>0 0 0 0 -0 0</wrench>
        </link>
      </model>
      <model name='online_models'>
        <pose>1.55493 0.397761 0.057885 0 -0 0</pose>
        <scale>1 1 1</scale>
        <model name='youbot'>
          <pose>0.858305 0.862366 0.09 0 -0 0</pose>
          <scale>1 1 1</scale>
          <link name='arm_link_0'>
            <pose>1.0013 0.862366 0.136 0 -0 0</pose>
            <velocity>0 0 0 0 -0 0</velocity>
            <acceleration>0 0 0 0 -0 0</acceleration>
            <wrench>0 0 0 0 -0 0</wrench>
          </link>
          <link name='arm_link_1'>
            <pose>1.0253 0.862366 0.232 0 -0 2.96706</pose>
            <velocity>0 0 0 0 -0 0</velocity>
            <acceleration>0 0 0 0 -0 0</acceleration>
            <wrench>0 0 0 0 -0 0</wrench>
          </link>
          <link name='arm_link_2'>
            <pose>0.992806 0.868096 0.251 0 -1.13446 2.96706</pose>
            <velocity>0 0 0 0 -0 0</velocity>
            <acceleration>0 0 0 0 -0 0</acceleration>
            <wrench>0 0 0 0 -0 0</wrench>
          </link>
          <link name='arm_link_3'>
            <pose>1.13115 0.843703 0.316506 -0 1.41372 2.96706</pose>
            <velocity>0 0 0 0 -0 0</velocity>
            <acceleration>0 0 0 0 -0 0</acceleration>
            <wrench>0 0 0 0 -0 0</wrench>
          </link>
          <link name='arm_link_4'>
            <pose>0.999838 0.866857 0.337624 0 -0.375246 2.96706</pose>
            <velocity>0 0 0 0 -0 0</velocity>
            <acceleration>0 0 0 0 -0 0</acceleration>
            <wrench>0 0 0 0 -0 0</wrench>
          </link>
          <link name='arm_link_5'>
            <pose>1.04859 0.85826 0.457846 -0.085052 0.365926 -0.408445</pose>
            <velocity>0 0 0 0 -0 0</velocity>
            <acceleration>0 0 0 0 -0 0</acceleration>
            <wrench>0 0 0 0 -0 0</wrench>
          </link>
          <link name='base_footprint'>
            <pose>0.858305 0.862366 0.09 0 -0 0</pose>
            <velocity>0 0 0 0 -0 0</velocity>
            <acceleration>0 0 0 0 -0 0</acceleration>
            <wrench>0 0 0 0 -0 0</wrench>
          </link>
          <link name='base_laser_front_link'>
            <pose>1.1583 0.862366 0.06 0 -0 0</pose>
            <velocity>0 0 0 0 -0 0</velocity>
            <acceleration>0 0 0 0 -0 0</acceleration>
            <wrench>0 0 0 0 -0 0</wrench>
          </link>
          <link name='base_link'>
            <pose>0.858305 0.862366 0.09 0 -0 0</pose>
            <velocity>0 0 0 0 -0 0</velocity>
            <acceleration>0 0 0 0 -0 0</acceleration>
            <wrench>0 0 0 0 -0 0</wrench>
          </link>
          <link name='caster_link_bl'>
            <pose>0.630305 1.02037 0.056 0 -0 0</pose>
            <velocity>0 0 0 0 -0 0</velocity>
            <acceleration>0 0 0 0 -0 0</acceleration>
            <wrench>0 0 0 0 -0 0</wrench>
          </link>
          <link name='caster_link_br'>
            <pose>0.630305 0.704366 0.056 0 -0 0</pose>
            <velocity>0 0 0 0 -0 0</velocity>
            <acceleration>0 0 0 0 -0 0</acceleration>
            <wrench>0 0 0 0 -0 0</wrench>
          </link>
          <link name='caster_link_fl'>
            <pose>1.08631 1.02037 0.056 0 -0 0</pose>
            <velocity>0 0 0 0 -0 0</velocity>
            <acceleration>0 0 0 0 -0 0</acceleration>
            <wrench>0 0 0 0 -0 0</wrench>
          </link>
          <link name='caster_link_fr'>
            <pose>1.08631 0.704366 0.056 0 -0 0</pose>
            <velocity>0 0 0 0 -0 0</velocity>
            <acceleration>0 0 0 0 -0 0</acceleration>
            <wrench>0 0 0 0 -0 0</wrench>
          </link>
          <link name='gripper_finger_link_l'>
            <pose>1.07157 0.861261 0.498579 0.085052 -0.365926 2.73315</pose>
            <velocity>0 0 0 0 -0 0</velocity>
            <acceleration>0 0 0 0 -0 0</acceleration>
            <wrench>0 0 0 0 -0 0</wrench>
          </link>
          <link name='gripper_finger_link_r'>
            <pose>1.06568 0.846437 0.499848 -0.085052 0.365926 -0.408445</pose>
            <velocity>0 0 0 0 -0 0</velocity>
            <acceleration>0 0 0 0 -0 0</acceleration>
            <wrench>0 0 0 0 -0 0</wrench>
          </link>
          <link name='gripper_palm_link'>
            <pose>1.04859 0.85826 0.457846 -0.085052 0.365926 -0.408445</pose>
            <velocity>0 0 0 0 -0 0</velocity>
            <acceleration>0 0 0 0 -0 0</acceleration>
            <wrench>0 0 0 0 -0 0</wrench>
          </link>
          <link name='plate_link'>
            <pose>0.699305 0.862366 0.136 0 -0 0</pose>
            <velocity>0 0 0 0 -0 0</velocity>
            <acceleration>0 0 0 0 -0 0</acceleration>
            <wrench>0 0 0 0 -0 0</wrench>
          </link>
          <link name='wheel_link_bl'>
            <pose>0.630305 1.02037 0.056 0 -0 0</pose>
            <velocity>0 0 0 0 -0 0</velocity>
            <acceleration>0 0 0 0 -0 0</acceleration>
            <wrench>0 0 0 0 -0 0</wrench>
          </link>
          <link name='wheel_link_br'>
            <pose>0.630305 0.704366 0.056 0 -0 0</pose>
            <velocity>0 0 0 0 -0 0</velocity>
            <acceleration>0 0 0 0 -0 0</acceleration>
            <wrench>0 0 0 0 -0 0</wrench>
          </link>
          <link name='wheel_link_fl'>
            <pose>1.08631 1.02037 0.056 0 -0 0</pose>
            <velocity>0 0 0 0 -0 0</velocity>
            <acceleration>0 0 0 0 -0 0</acceleration>
            <wrench>0 0 0 0 -0 0</wrench>
          </link>
          <link name='wheel_link_fr'>
            <pose>1.08631 0.704366 0.056 0 -0 0</pose>
            <velocity>0 0 0 0 -0 0</velocity>
            <acceleration>0 0 0 0 -0 0</acceleration>
            <wrench>0 0 0 0 -0 0</wrench>
          </link>
        </model>
        <model name='zephyr_delta_wing'>
          <pose>2.25155 -0.066844 0.02577 0 0 -1.43936</pose>
          <scale>1 1 1</scale>
          <link name='flap_left'>
            <pose>2.54786 -0.484614 0.03277 0 0 -1.43936</pose>
            <velocity>0 0 0 0 -0 0</velocity>
            <acceleration>0 0 0 0 -0 0</acceleration>
            <wrench>0 0 0 0 -0 0</wrench>
          </link>
          <link name='flap_right'>
            <pose>2.42912 0.413572 0.03277 0 0 -1.43936</pose>
            <velocity>0 0 0 0 -0 0</velocity>
            <acceleration>0 0 0 0 -0 0</acceleration>
            <wrench>0 0 0 0 -0 0</wrench>
          </link>
          <link name='propeller'>
            <pose>2.32095 -0.05767 0.03377 0 1.5707 -1.43936</pose>
            <velocity>0 0 0 0 -0 0</velocity>
            <acceleration>0 0 0 0 -0 0</acceleration>
            <wrench>0 0 0 0 -0 0</wrench>
          </link>
          <link name='wing'>
            <pose>2.25155 -0.066844 0.02577 0 0 -1.43936</pose>
            <velocity>0 0 0 0 -0 0</velocity>
            <acceleration>0 0 0 0 -0 0</acceleration>
            <wrench>0 0 0 0 -0 0</wrench>
          </link>
        </model>
      </model>
      <model name='robot'>
        <pose>0.000126 0.008159 0.069996 1.4e-05 7e-06 -0.000919</pose>
        <scale>1 1 1</scale>
        <link name='link_0'>
          <pose>0.000115 -0.00213 0.069996 1.4e-05 7e-06 -0.000919</pose>
          <velocity>0.000453 -0.000175 -0.004692 0.013862 0.007656 -0.000346</velocity>
          <acceleration>0.306227 -0.035171 -4.74122 0.250454 -1.55964 2.87975</acceleration>
          <wrench>0.306227 -0.035171 -4.74122 0 -0 0</wrench>
        </link>
        <link name='link_1_clone_0'>
          <pose>-0.154665 0.248012 0.07 1.57071 -0.026208 1.56978</pose>
          <velocity>0.000537 -0.000124 -3.7e-05 0.001741 0.00767 -0.000348</velocity>
          <acceleration>0.332059 0.004746 -0.02101 -0.10157 -1.5469 -0.228166</acceleration>
          <wrench>0.332059 0.004746 -0.02101 0 -0 0</wrench>
        </link>
        <link name='link_1_clone_0_clone'>
          <pose>0.155369 0.259171 0.069999 1.57071 -4.2e-05 1.56978</pose>
          <velocity>0.000544 -0.000226 -0.00255 -0.000228 0.007666 -0.00035</velocity>
          <acceleration>0.382578 -0.078376 -1.65065 1.62519 -1.56694 2.89913</acceleration>
          <wrench>0.382578 -0.078376 -1.65065 0 -0 0</wrench>
        </link>
        <link name='link_1_clone_0_clone_0'>
          <pose>0.154918 -0.232271 0.069992 1.57071 -0.033581 1.56978</pose>
          <velocity>0.000377 -0.000233 -0.009067 0.001687 0.007659 -0.000349</velocity>
          <acceleration>0.236237 -0.07413 -9.14611 -3.13679 -1.56855 2.91113</acceleration>
          <wrench>0.236237 -0.07413 -9.14611 0 -0 0</wrench>
        </link>
        <link name='link_1_clone_0_clone_0_clone'>
          <pose>-0.155109 -0.231986 0.069994 1.57071 -0.030295 1.56978</pose>
          <velocity>0.000353 -0.000118 -0.006693 0.001957 0.007673 -0.000353</velocity>
          <acceleration>0.15018 0.018642 -7.69374 0.004853 -1.52848 -0.24362</acceleration>
          <wrench>0.15018 0.018642 -7.69374 0 -0 0</wrench>
        </link>
      </model>
      <light name='sun'>
        <pose>0 0 10 0 -0 0</pose>
      </light>
    </state>
    <gui fullscreen='0'>
      <camera name='user_camera'>
        <pose>-11.4091 8.85762 6.31725 -0 0.315641 -0.707012</pose>
        <view_controller>orbit</view_controller>
        <projection_type>perspective</projection_type>
      </camera>
    </gui>
    <model name='mybuilding'>
      <pose>-1.50073 -2.44259 0 0 -0 0</pose>
      <link name='Wall_0'>
        <pose>-3.68927 1.71259 0 0 -0 0</pose>
        <visual name='Wall_0_Visual_0'>
          <pose>-2.16475 0 0.25 0 -0 0</pose>
          <geometry>
            <box>
              <size>0.6605 0.15 0.5</size>
            </box>
          </geometry>
          <material>
            <script>
              <uri>file://media/materials/scripts/gazebo.material</uri>
              <name>Gazebo/Bricks</name>
            </script>
            <ambient>1 0.764706 0.305882 1</ambient>
          </material>
          <meta>
            <layer>0</layer>
          </meta>
        </visual>
        <collision name='Wall_0_Collision_0'>
          <geometry>
            <box>
              <size>0.6605 0.15 0.5</size>
            </box>
          </geometry>
          <pose>-2.16475 0 0.25 0 -0 0</pose>
          <surface>
            <contact>
              <ode/>
            </contact>
            <bounce/>
            <friction>
              <torsional>
                <ode/>
              </torsional>
              <ode/>
            </friction>
          </surface>
          <max_contacts>10</max_contacts>
        </collision>
        <visual name='Wall_0_Visual_1'>
          <pose>0.78025 0 0.25 0 -0 0</pose>
          <geometry>
            <box>
              <size>3.4295 0.15 0.5</size>
            </box>
          </geometry>
          <material>
            <script>
              <uri>file://media/materials/scripts/gazebo.material</uri>
              <name>Gazebo/Bricks</name>
            </script>
            <ambient>1 0.764706 0.305882 1</ambient>
          </material>
          <meta>
            <layer>0</layer>
          </meta>
        </visual>
        <collision name='Wall_0_Collision_1'>
          <geometry>
            <box>
              <size>3.4295 0.15 0.5</size>
            </box>
          </geometry>
          <pose>0.78025 0 0.25 0 -0 0</pose>
          <surface>
            <contact>
              <ode/>
            </contact>
            <bounce/>
            <friction>
              <torsional>
                <ode/>
              </torsional>
              <ode/>
            </friction>
          </surface>
          <max_contacts>10</max_contacts>
        </collision>
        <self_collide>0</self_collide>
        <enable_wind>0</enable_wind>
        <kinematic>0</kinematic>
      </link>
      <link name='Wall_1'>
        <collision name='Wall_1_Collision'>
          <geometry>
            <box>
              <size>2.45586 0.15 0.5</size>
            </box>
          </geometry>
          <pose>0 0 0.25 0 -0 0</pose>
          <surface>
            <contact>
              <ode/>
            </contact>
            <bounce/>
            <friction>
              <torsional>
                <ode/>
              </torsional>
              <ode/>
            </friction>
          </surface>
          <max_contacts>10</max_contacts>
        </collision>
        <visual name='Wall_1_Visual'>
          <pose>0 0 0.25 0 -0 0</pose>
          <geometry>
            <box>
              <size>2.45586 0.15 0.5</size>
            </box>
          </geometry>
          <material>
            <script>
              <uri>file://media/materials/scripts/gazebo.material</uri>
              <name>Gazebo/Bricks</name>
            </script>
            <ambient>1 0.764706 0.305882 1</ambient>
          </material>
          <meta>
            <layer>0</layer>
          </meta>
        </visual>
        <pose>-0.434273 0.917593 0 0 -0 -0.760863</pose>
        <self_collide>0</self_collide>
        <enable_wind>0</enable_wind>
        <kinematic>0</kinematic>
      </link>
      <link name='Wall_10'>
        <pose>0.150727 -2.32741 0 0 -0 3.14159</pose>
        <visual name='Wall_10_Visual_0'>
          <pose>0 0 0.25 0 -0 0</pose>
          <geometry>
            <box>
              <size>2.25 0.15 0.5</size>
            </box>
          </geometry>
          <material>
            <script>
              <uri>file://media/materials/scripts/gazebo.material</uri>
              <name>Gazebo/Bricks</name>
            </script>
            <ambient>1 0.764706 0.305882 1</ambient>
          </material>
          <meta>
            <layer>0</layer>
          </meta>
        </visual>
        <collision name='Wall_10_Collision_0'>
          <geometry>
            <box>
              <size>2.25 0.15 0.5</size>
            </box>
          </geometry>
          <pose>0 0 0.25 0 -0 0</pose>
          <surface>
            <contact>
              <ode/>
            </contact>
            <bounce/>
            <friction>
              <torsional>
                <ode/>
              </torsional>
              <ode/>
            </friction>
          </surface>
          <max_contacts>10</max_contacts>
        </collision>
        <self_collide>0</self_collide>
        <enable_wind>0</enable_wind>
        <kinematic>0</kinematic>
      </link>
      <link name='Wall_11'>
        <collision name='Wall_11_Collision'>
          <geometry>
            <box>
              <size>1.25 0.15 0.5</size>
            </box>
          </geometry>
          <pose>0 0 0.25 0 -0 0</pose>
          <surface>
            <contact>
              <ode/>
            </contact>
            <bounce/>
            <friction>
              <torsional>
                <ode/>
              </torsional>
              <ode/>
            </friction>
          </surface>
          <max_contacts>10</max_contacts>
        </collision>
        <visual name='Wall_11_Visual'>
          <pose>0 0 0.25 0 -0 0</pose>
          <geometry>
            <box>
              <size>1.25 0.15 0.5</size>
            </box>
          </geometry>
          <material>
            <script>
              <uri>file://media/materials/scripts/gazebo.material</uri>
              <name>Gazebo/Bricks</name>
            </script>
            <ambient>1 0.764706 0.305882 1</ambient>
          </material>
          <meta>
            <layer>0</layer>
          </meta>
        </visual>
        <pose>-0.899273 -1.77741 0 0 -0 1.5708</pose>
        <self_collide>0</self_collide>
        <enable_wind>0</enable_wind>
        <kinematic>0</kinematic>
      </link>
      <link name='Wall_12'>
        <collision name='Wall_12_Collision'>
          <geometry>
            <box>
              <size>3.67065 0.15 0.5</size>
            </box>
          </geometry>
          <pose>0 0 0.25 0 -0 0</pose>
          <surface>
            <contact>
              <ode/>
            </contact>
            <bounce/>
            <friction>
              <torsional>
                <ode/>
              </torsional>
              <ode/>
            </friction>
          </surface>
          <max_contacts>10</max_contacts>
        </collision>
        <visual name='Wall_12_Visual'>
          <pose>0 0 0.25 0 -0 0</pose>
          <geometry>
            <box>
              <size>3.67065 0.15 0.5</size>
            </box>
          </geometry>
          <material>
            <script>
              <uri>file://media/materials/scripts/gazebo.material</uri>
              <name>Gazebo/Bricks</name>
            </script>
            <ambient>1 0.764706 0.305882 1</ambient>
          </material>
          <meta>
            <layer>0</layer>
          </meta>
        </visual>
        <pose>-2.6596 -1.22741 0 0 -0 3.14159</pose>
        <self_collide>0</self_collide>
        <enable_wind>0</enable_wind>
        <kinematic>0</kinematic>
      </link>
      <link name='Wall_13'>
        <collision name='Wall_13_Collision'>
          <geometry>
            <box>
              <size>1.25 0.15 0.5</size>
            </box>
          </geometry>
          <pose>0 0 0.25 0 -0 0</pose>
          <surface>
            <contact>
              <ode/>
            </contact>
            <bounce/>
            <friction>
              <torsional>
                <ode/>
              </torsional>
              <ode/>
            </friction>
          </surface>
          <max_contacts>10</max_contacts>
        </collision>
        <visual name='Wall_13_Visual'>
          <pose>0 0 0.25 0 -0 0</pose>
          <geometry>
            <box>
              <size>1.25 0.15 0.5</size>
            </box>
          </geometry>
          <material>
            <script>
              <uri>file://media/materials/scripts/gazebo.material</uri>
              <name>Gazebo/Bricks</name>
            </script>
            <ambient>1 0.764706 0.305882 1</ambient>
          </material>
          <meta>
            <layer>0</layer>
          </meta>
        </visual>
        <pose>-4.43976 -1.77741 0 0 -0 -1.53474</pose>
        <self_collide>0</self_collide>
        <enable_wind>0</enable_wind>
        <kinematic>0</kinematic>
      </link>
      <link name='Wall_14'>
        <collision name='Wall_14_Collision'>
          <geometry>
            <box>
              <size>1.9 0.15 0.5</size>
            </box>
          </geometry>
          <pose>0 0 0.25 0 -0 0</pose>
          <surface>
            <contact>
              <ode/>
            </contact>
            <bounce/>
            <friction>
              <torsional>
                <ode/>
              </torsional>
              <ode/>
            </friction>
          </surface>
          <max_contacts>10</max_contacts>
        </collision>
        <visual name='Wall_14_Visual'>
          <pose>0 0 0.25 0 -0 0</pose>
          <geometry>
            <box>
              <size>1.9 0.15 0.5</size>
            </box>
          </geometry>
          <material>
            <script>
              <uri>file://media/materials/scripts/gazebo.material</uri>
              <name>Gazebo/Bricks</name>
            </script>
            <ambient>1 0.764706 0.305882 1</ambient>
          </material>
          <meta>
            <layer>0</layer>
          </meta>
        </visual>
        <pose>-5.29471 -2.34653 0 0 -0 -3.11973</pose>
        <self_collide>0</self_collide>
        <enable_wind>0</enable_wind>
        <kinematic>0</kinematic>
      </link>
      <link name='Wall_15'>
        <collision name='Wall_15_Collision'>
          <geometry>
            <box>
              <size>4.25 0.15 0.5</size>
            </box>
          </geometry>
          <pose>0 0 0.25 0 -0 0</pose>
          <surface>
            <contact>
              <ode/>
            </contact>
            <bounce/>
            <friction>
              <torsional>
                <ode/>
              </torsional>
              <ode/>
            </friction>
          </surface>
          <max_contacts>10</max_contacts>
        </collision>
        <visual name='Wall_15_Visual'>
          <pose>0 0 0.25 0 -0 0</pose>
          <geometry>
            <box>
              <size>4.25 0.15 0.5</size>
            </box>
          </geometry>
          <material>
            <script>
              <uri>file://media/materials/scripts/gazebo.material</uri>
              <name>Gazebo/Bricks</name>
            </script>
            <ambient>1 0.764706 0.305882 1</ambient>
          </material>
          <meta>
            <layer>0</layer>
          </meta>
        </visual>
        <pose>-6.20939 -0.316535 0 0 -0 1.59026</pose>
        <self_collide>0</self_collide>
        <enable_wind>0</enable_wind>
        <kinematic>0</kinematic>
      </link>
      <link name='Wall_2'>
        <collision name='Wall_2_Collision'>
          <geometry>
            <box>
              <size>6 0.15 0.5</size>
            </box>
          </geometry>
          <pose>0 0 0.25 0 -0 0</pose>
          <surface>
            <contact>
              <ode/>
            </contact>
            <bounce/>
            <friction>
              <torsional>
                <ode/>
              </torsional>
              <ode/>
            </friction>
          </surface>
          <max_contacts>10</max_contacts>
        </collision>
        <visual name='Wall_2_Visual'>
          <pose>0 0 0.25 0 -0 0</pose>
          <geometry>
            <box>
              <size>6 0.15 0.5</size>
            </box>
          </geometry>
          <material>
            <script>
              <uri>file://media/materials/scripts/gazebo.material</uri>
              <name>Gazebo/Bricks</name>
            </script>
            <ambient>1 0.764706 0.305882 1</ambient>
          </material>
          <meta>
            <layer>0</layer>
          </meta>
        </visual>
        <pose>3.32573 0.122593 0 0 -0 0</pose>
        <self_collide>0</self_collide>
        <enable_wind>0</enable_wind>
        <kinematic>0</kinematic>
      </link>
      <link name='Wall_3'>
        <collision name='Wall_3_Collision'>
          <geometry>
            <box>
              <size>1.75 0.15 0.5</size>
            </box>
          </geometry>
          <pose>0 0 0.25 0 -0 0</pose>
          <surface>
            <contact>
              <ode/>
            </contact>
            <bounce/>
            <friction>
              <torsional>
                <ode/>
              </torsional>
              <ode/>
            </friction>
          </surface>
          <max_contacts>10</max_contacts>
        </collision>
        <visual name='Wall_3_Visual'>
          <pose>0 0 0.25 0 -0 0</pose>
          <geometry>
            <box>
              <size>1.75 0.15 0.5</size>
            </box>
          </geometry>
          <material>
            <script>
              <uri>file://media/materials/scripts/gazebo.material</uri>
              <name>Gazebo/Bricks</name>
            </script>
            <ambient>1 0.764706 0.305882 1</ambient>
          </material>
          <meta>
            <layer>0</layer>
          </meta>
        </visual>
        <pose>6.25073 -0.677407 0 0 -0 -1.5708</pose>
        <self_collide>0</self_collide>
        <enable_wind>0</enable_wind>
        <kinematic>0</kinematic>
      </link>
      <link name='Wall_4'>
        <collision name='Wall_4_Collision'>
          <geometry>
            <box>
              <size>2 0.15 0.5</size>
            </box>
          </geometry>
          <pose>0 0 0.25 0 -0 0</pose>
          <surface>
            <contact>
              <ode/>
            </contact>
            <bounce/>
            <friction>
              <torsional>
                <ode/>
              </torsional>
              <ode/>
            </friction>
          </surface>
          <max_contacts>10</max_contacts>
        </collision>
        <visual name='Wall_4_Visual'>
          <pose>0 0 0.25 0 -0 0</pose>
          <geometry>
            <box>
              <size>2 0.15 0.5</size>
            </box>
          </geometry>
          <material>
            <script>
              <uri>file://media/materials/scripts/gazebo.material</uri>
              <name>Gazebo/Bricks</name>
            </script>
            <ambient>1 0.764706 0.305882 1</ambient>
          </material>
          <meta>
            <layer>0</layer>
          </meta>
        </visual>
        <pose>5.32573 -1.47741 0 0 -0 3.14159</pose>
        <self_collide>0</self_collide>
        <enable_wind>0</enable_wind>
        <kinematic>0</kinematic>
      </link>
      <link name='Wall_5'>
        <collision name='Wall_5_Collision'>
          <geometry>
            <box>
              <size>1 0.15 0.5</size>
            </box>
          </geometry>
          <pose>0 0 0.25 0 -0 0</pose>
          <surface>
            <contact>
              <ode/>
            </contact>
            <bounce/>
            <friction>
              <torsional>
                <ode/>
              </torsional>
              <ode/>
            </friction>
          </surface>
          <max_contacts>10</max_contacts>
        </collision>
        <visual name='Wall_5_Visual'>
          <pose>0 0 0.25 0 -0 0</pose>
          <geometry>
            <box>
              <size>1 0.15 0.5</size>
            </box>
          </geometry>
          <material>
            <script>
              <uri>file://media/materials/scripts/gazebo.material</uri>
              <name>Gazebo/CeilingTiled</name>
            </script>
            <ambient>1 0.764706 0.305882 1</ambient>
          </material>
          <meta>
            <layer>0</layer>
          </meta>
        </visual>
        <pose>4.40073 -1.90241 0 0 -0 -1.5708</pose>
        <self_collide>0</self_collide>
        <enable_wind>0</enable_wind>
        <kinematic>0</kinematic>
      </link>
      <link name='Wall_6'>
        <pose>3.72573 -2.32741 0 0 -0 3.14159</pose>
        <visual name='Wall_6_Visual_0'>
          <pose>0 0 0.25 0 -0 0</pose>
          <geometry>
            <box>
              <size>1.5 0.15 0.5</size>
            </box>
          </geometry>
          <material>
            <script>
              <uri>file://media/materials/scripts/gazebo.material</uri>
              <name>Gazebo/Bricks</name>
            </script>
            <ambient>1 0.764706 0.305882 1</ambient>
          </material>
          <meta>
            <layer>0</layer>
          </meta>
        </visual>
        <collision name='Wall_6_Collision_0'>
          <geometry>
            <box>
              <size>1.5 0.15 0.5</size>
            </box>
          </geometry>
          <pose>0 0 0.25 0 -0 0</pose>
          <surface>
            <contact>
              <ode/>
            </contact>
            <bounce/>
            <friction>
              <torsional>
                <ode/>
              </torsional>
              <ode/>
            </friction>
          </surface>
          <max_contacts>10</max_contacts>
        </collision>
        <self_collide>0</self_collide>
        <enable_wind>0</enable_wind>
        <kinematic>0</kinematic>
      </link>
      <link name='Wall_7'>
        <collision name='Wall_7_Collision'>
          <geometry>
            <box>
              <size>1 0.15 0.5</size>
            </box>
          </geometry>
          <pose>0 0 0.25 0 -0 0</pose>
          <surface>
            <contact>
              <ode/>
            </contact>
            <bounce/>
            <friction>
              <torsional>
                <ode/>
              </torsional>
              <ode/>
            </friction>
          </surface>
          <max_contacts>10</max_contacts>
        </collision>
        <visual name='Wall_7_Visual'>
          <pose>0 0 0.25 0 -0 0</pose>
          <geometry>
            <box>
              <size>1 0.15 0.5</size>
            </box>
          </geometry>
          <material>
            <script>
              <uri>file://media/materials/scripts/gazebo.material</uri>
              <name>Gazebo/Bricks</name>
            </script>
            <ambient>1 0.764706 0.305882 1</ambient>
          </material>
          <meta>
            <layer>0</layer>
          </meta>
        </visual>
        <pose>3.05073 -1.90241 0 0 -0 1.5708</pose>
        <self_collide>0</self_collide>
        <enable_wind>0</enable_wind>
        <kinematic>0</kinematic>
      </link>
      <link name='Wall_8'>
        <collision name='Wall_8_Collision'>
          <geometry>
            <box>
              <size>2 0.15 0.5</size>
            </box>
          </geometry>
          <pose>0 0 0.25 0 -0 0</pose>
          <surface>
            <contact>
              <ode/>
            </contact>
            <bounce/>
            <friction>
              <torsional>
                <ode/>
              </torsional>
              <ode/>
            </friction>
          </surface>
          <max_contacts>10</max_contacts>
        </collision>
        <visual name='Wall_8_Visual'>
          <pose>0 0 0.25 0 -0 0</pose>
          <geometry>
            <box>
              <size>2 0.15 0.5</size>
            </box>
          </geometry>
          <material>
            <script>
              <uri>file://media/materials/scripts/gazebo.material</uri>
              <name>Gazebo/Bricks</name>
            </script>
            <ambient>1 0.764706 0.305882 1</ambient>
          </material>
          <meta>
            <layer>0</layer>
          </meta>
        </visual>
        <pose>2.12573 -1.47741 0 0 -0 3.14159</pose>
        <self_collide>0</self_collide>
        <enable_wind>0</enable_wind>
        <kinematic>0</kinematic>
      </link>
      <link name='Wall_9'>
        <collision name='Wall_9_Collision'>
          <geometry>
            <box>
              <size>1 0.15 0.5</size>
            </box>
          </geometry>
          <pose>0 0 0.25 0 -0 0</pose>
          <surface>
            <contact>
              <ode/>
            </contact>
            <bounce/>
            <friction>
              <torsional>
                <ode/>
              </torsional>
              <ode/>
            </friction>
          </surface>
          <max_contacts>10</max_contacts>
        </collision>
        <visual name='Wall_9_Visual'>
          <pose>0 0 0.25 0 -0 0</pose>
          <geometry>
            <box>
              <size>1 0.15 0.5</size>
            </box>
          </geometry>
          <material>
            <script>
              <uri>file://media/materials/scripts/gazebo.material</uri>
              <name>Gazebo/Bricks</name>
            </script>
            <ambient>1 0.764706 0.305882 1</ambient>
          </material>
          <meta>
            <layer>0</layer>
          </meta>
        </visual>
        <pose>1.20073 -1.90241 0 0 -0 -1.5708</pose>
        <self_collide>0</self_collide>
        <enable_wind>0</enable_wind>
        <kinematic>0</kinematic>
      </link>
      <static>1</static>
    </model>
    <model name='online_models'>
      <model name='youbot'>
        <pose>-0.696625 0.464605 0.032115 0 -0 0</pose>
        <link name='base_footprint'>
          <pose>0 0 0 0 -0 0</pose>
          <inertial>
            <pose>0 0 -0.05 0 -0 0</pose>
            <inertia>
              <ixx>1</ixx>
              <ixy>0</ixy>
              <ixz>0</ixz>
              <iyy>1</iyy>
              <iyz>0</iyz>
              <izz>1</izz>
            </inertia>
            <mass>0.1</mass>
          </inertial>
          <collision name='base_footprint_geom'>
            <pose>0 0 -0.05 0 -0 0</pose>
            <geometry>
              <box>
                <size>0.001 0.001 0.001</size>
              </box>
            </geometry>
            <surface>
              <friction>
                <ode>
                  <mu>0</mu>
                  <mu2>0</mu2>
                  <fdir1>0 0 0</fdir1>
                  <slip1>0</slip1>
                  <slip2>0</slip2>
                </ode>
                <torsional>
                  <ode/>
                </torsional>
              </friction>
              <bounce>
                <restitution_coefficient>0</restitution_coefficient>
                <threshold>0</threshold>
              </bounce>
              <contact>
                <ode>
                  <soft_cfm>0</soft_cfm>
                  <soft_erp>0.2</soft_erp>
                  <kp>1e+13</kp>
                  <kd>1e+11</kd>
                  <max_vel>-1</max_vel>
                  <min_depth>0</min_depth>
                </ode>
              </contact>
            </surface>
            <laser_retro>0</laser_retro>
            <max_contacts>10</max_contacts>
          </collision>
          <visual name='base_footprint_geom_visual'>
            <pose>0 0 0 0 -0 0</pose>
            <geometry>
              <box>
                <size>0.001 0.001 0.001</size>
              </box>
            </geometry>
          </visual>
          <gravity>1</gravity>
          <self_collide>0</self_collide>
          <kinematic>0</kinematic>
          <enable_wind>0</enable_wind>
        </link>
        <link name='base_link'>
          <pose>0 0 0 0 -0 0</pose>
          <inertial>
            <pose>0 0 0 0 -0 0</pose>
            <inertia>
              <ixx>5.65223</ixx>
              <ixy>-0.00972</ixy>
              <ixz>1.29399</ixz>
              <iyy>5.66947</iyy>
              <iyz>-0.00738</iyz>
              <izz>3.6832</izz>
            </inertia>
            <mass>22</mass>
          </inertial>
          <collision name='base_link_geom'>
            <pose>0 0 0 0 -0 0</pose>
            <geometry>
              <mesh>
                <uri>model://youbot/meshes/base/base_convex.stl</uri>
              </mesh>
            </geometry>
            <surface>
              <friction>
                <ode>
                  <mu>0</mu>
                  <mu2>0</mu2>
                  <fdir1>0 0 0</fdir1>
                  <slip1>0</slip1>
                  <slip2>0</slip2>
                </ode>
                <torsional>
                  <ode/>
                </torsional>
              </friction>
              <bounce>
                <restitution_coefficient>0</restitution_coefficient>
                <threshold>0</threshold>
              </bounce>
              <contact>
                <ode>
                  <soft_cfm>0</soft_cfm>
                  <soft_erp>0.2</soft_erp>
                  <kp>1e+13</kp>
                  <kd>1e+11</kd>
                  <max_vel>-1</max_vel>
                  <min_depth>0</min_depth>
                </ode>
              </contact>
            </surface>
            <laser_retro>0</laser_retro>
            <max_contacts>10</max_contacts>
          </collision>
          <visual name='base_link_geom_visual'>
            <pose>0 0 0 0 -0 0</pose>
            <geometry>
              <mesh>
                <uri>model://youbot/meshes/base/base.dae</uri>
              </mesh>
            </geometry>
          </visual>
          <gravity>1</gravity>
          <self_collide>0</self_collide>
          <kinematic>0</kinematic>
          <enable_wind>0</enable_wind>
        </link>
        <link name='arm_link_0'>
          <pose>0.143 0 0.046 0 -0 0</pose>
          <inertial>
            <pose>0 0 0 0 -0 0</pose>
            <inertia>
              <ixx>0.01</ixx>
              <ixy>0</ixy>
              <ixz>0</ixz>
              <iyy>0.01</iyy>
              <iyz>0</iyz>
              <izz>0.01</izz>
            </inertia>
            <mass>0.845</mass>
          </inertial>
          <collision name='arm_link_0_geom'>
            <pose>0 0 0 0 -0 0</pose>
            <geometry>
              <mesh>
                <uri>model://youbot/meshes/arm/arm0_convex.stl</uri>
              </mesh>
            </geometry>
            <surface>
              <friction>
                <ode>
                  <mu>0</mu>
                  <mu2>0</mu2>
                  <fdir1>0 0 0</fdir1>
                  <slip1>0</slip1>
                  <slip2>0</slip2>
                </ode>
                <torsional>
                  <ode/>
                </torsional>
              </friction>
              <bounce>
                <restitution_coefficient>0</restitution_coefficient>
                <threshold>0</threshold>
              </bounce>
              <contact>
                <ode>
                  <soft_cfm>0</soft_cfm>
                  <soft_erp>0.2</soft_erp>
                  <kp>1e+13</kp>
                  <kd>1e+11</kd>
                  <max_vel>-1</max_vel>
                  <min_depth>0</min_depth>
                </ode>
              </contact>
            </surface>
            <laser_retro>0</laser_retro>
            <max_contacts>10</max_contacts>
          </collision>
          <visual name='arm_link_0_geom_visual'>
            <pose>0 0 0 0 -0 0</pose>
            <geometry>
              <mesh>
                <uri>model://youbot/meshes/arm/arm0.dae</uri>
              </mesh>
            </geometry>
            <material>
              <script>
                <uri>model://youbot/materials/scripts/youbot.material</uri>
                <name>youbot/DarkGrey</name>
              </script>
            </material>
          </visual>
          <gravity>1</gravity>
          <self_collide>0</self_collide>
          <kinematic>0</kinematic>
          <enable_wind>0</enable_wind>
        </link>
        <link name='arm_link_1'>
          <pose>0.167 0 0.142 0 -0 2.96706</pose>
          <inertial>
            <pose>0.01489 0.00213 0.00213 0 -0 0</pose>
            <inertia>
              <ixx>0.003863</ixx>
              <ixy>-0.000979</ixy>
              <ixz>0</ixz>
              <iyy>0.006196</iyy>
              <iyz>0</iyz>
              <izz>0.006369</izz>
            </inertia>
            <mass>2.412</mass>
          </inertial>
          <collision name='arm_link_1_geom'>
            <pose>0 0 0 0 -0 0</pose>
            <geometry>
              <mesh>
                <uri>model://youbot/meshes/arm/arm1_convex.stl</uri>
              </mesh>
            </geometry>
            <surface>
              <friction>
                <ode>
                  <mu>0</mu>
                  <mu2>0</mu2>
                  <fdir1>0 0 0</fdir1>
                  <slip1>0</slip1>
                  <slip2>0</slip2>
                </ode>
                <torsional>
                  <ode/>
                </torsional>
              </friction>
              <bounce>
                <restitution_coefficient>0</restitution_coefficient>
                <threshold>0</threshold>
              </bounce>
              <contact>
                <ode>
                  <soft_cfm>0</soft_cfm>
                  <soft_erp>0.2</soft_erp>
                  <kp>1e+13</kp>
                  <kd>1e+11</kd>
                  <max_vel>-1</max_vel>
                  <min_depth>0</min_depth>
                </ode>
              </contact>
            </surface>
            <laser_retro>0</laser_retro>
            <max_contacts>10</max_contacts>
          </collision>
          <visual name='arm_link_1_geom_visual'>
            <pose>0 0 0 0 -0 0</pose>
            <geometry>
              <mesh>
                <uri>model://youbot/meshes/arm/arm1.dae</uri>
              </mesh>
            </geometry>
          </visual>
          <gravity>1</gravity>
          <self_collide>0</self_collide>
          <kinematic>0</kinematic>
          <enable_wind>0</enable_wind>
        </link>
        <link name='arm_link_2'>
          <pose>0.134501 0.00573 0.161 0 -1.13446 2.96706</pose>
          <inertial>
            <pose>0.10453 0.0017 -0.00297 0 -0 0</pose>
            <inertia>
              <ixx>0.000823</ixx>
              <ixy>0</ixy>
              <ixz>-0</ixz>
              <iyy>0.004447</iyy>
              <iyz>0</iyz>
              <izz>0.004439</izz>
            </inertia>
            <mass>1.155</mass>
          </inertial>
          <collision name='arm_link_2_geom'>
            <pose>0 -0.032 0.078 0 -0 0</pose>
            <geometry>
              <mesh>
                <uri>model://youbot/meshes/arm/arm2_convex.stl</uri>
              </mesh>
            </geometry>
            <surface>
              <friction>
                <ode>
                  <mu>0</mu>
                  <mu2>0</mu2>
                  <fdir1>0 0 0</fdir1>
                  <slip1>0</slip1>
                  <slip2>0</slip2>
                </ode>
                <torsional>
                  <ode/>
                </torsional>
              </friction>
              <bounce>
                <restitution_coefficient>0</restitution_coefficient>
                <threshold>0</threshold>
              </bounce>
              <contact>
                <ode>
                  <soft_cfm>0</soft_cfm>
                  <soft_erp>0.2</soft_erp>
                  <kp>1e+13</kp>
                  <kd>1e+11</kd>
                  <max_vel>-1</max_vel>
                  <min_depth>0</min_depth>
                </ode>
              </contact>
            </surface>
            <laser_retro>0</laser_retro>
            <max_contacts>10</max_contacts>
          </collision>
          <visual name='arm_link_2_geom_visual'>
            <pose>0 -0.032 0.078 0 -0 0</pose>
            <geometry>
              <mesh>
                <uri>model://youbot/meshes/arm/arm2.dae</uri>
              </mesh>
            </geometry>
          </visual>
          <gravity>1</gravity>
          <self_collide>0</self_collide>
          <kinematic>0</kinematic>
          <enable_wind>0</enable_wind>
        </link>
        <link name='arm_link_3'>
          <pose>0.272845 -0.018663 0.226506 -0 1.41372 2.96706</pose>
          <inertial>
            <pose>0.0001 0.0967 0.02107 0 -0 0</pose>
            <inertia>
              <ixx>0.002459</ixx>
              <ixy>0</ixy>
              <ixz>0</ixz>
              <iyy>0.002571</iyy>
              <iyz>-0</iyz>
              <izz>0.000535</izz>
            </inertia>
            <mass>0.934</mass>
          </inertial>
          <collision name='arm_link_3_geom'>
            <pose>0 0.028 0.079 0 -0 0</pose>
            <geometry>
              <mesh>
                <uri>model://youbot/meshes/arm/arm3_convex.stl</uri>
              </mesh>
            </geometry>
            <surface>
              <friction>
                <ode>
                  <mu>0</mu>
                  <mu2>0</mu2>
                  <fdir1>0 0 0</fdir1>
                  <slip1>0</slip1>
                  <slip2>0</slip2>
                </ode>
                <torsional>
                  <ode/>
                </torsional>
              </friction>
              <bounce>
                <restitution_coefficient>0</restitution_coefficient>
                <threshold>0</threshold>
              </bounce>
              <contact>
                <ode>
                  <soft_cfm>0</soft_cfm>
                  <soft_erp>0.2</soft_erp>
                  <kp>1e+13</kp>
                  <kd>1e+11</kd>
                  <max_vel>-1</max_vel>
                  <min_depth>0</min_depth>
                </ode>
              </contact>
            </surface>
            <laser_retro>0</laser_retro>
            <max_contacts>10</max_contacts>
          </collision>
          <visual name='arm_link_3_geom_visual'>
            <pose>0 0.028 0.079 0 -0 0</pose>
            <geometry>
              <mesh>
                <uri>model://youbot/meshes/arm/arm3.dae</uri>
              </mesh>
            </geometry>
          </visual>
          <gravity>1</gravity>
          <self_collide>0</self_collide>
          <kinematic>0</kinematic>
          <enable_wind>0</enable_wind>
        </link>
        <link name='arm_link_4'>
          <pose>0.141533 0.004491 0.247624 0 -0.375246 2.96706</pose>
          <inertial>
            <pose>0.00011 0.05103 -0.02319 0 -0 0</pose>
            <inertia>
              <ixx>0.000869</ixx>
              <ixy>0</ixy>
              <ixz>-0</ixz>
              <iyy>0.001173</iyy>
              <iyz>-0.000231</iyz>
              <izz>0.001091</izz>
            </inertia>
            <mass>0.877</mass>
          </inertial>
          <collision name='arm_link_4_geom'>
            <pose>0 -0.01 0.029 0 -0 0</pose>
            <geometry>
              <mesh>
                <uri>model://youbot/meshes/arm/arm4_convex.stl</uri>
              </mesh>
            </geometry>
            <surface>
              <friction>
                <ode>
                  <mu>0</mu>
                  <mu2>0</mu2>
                  <fdir1>0 0 0</fdir1>
                  <slip1>0</slip1>
                  <slip2>0</slip2>
                </ode>
                <torsional>
                  <ode/>
                </torsional>
              </friction>
              <bounce>
                <restitution_coefficient>0</restitution_coefficient>
                <threshold>0</threshold>
              </bounce>
              <contact>
                <ode>
                  <soft_cfm>0</soft_cfm>
                  <soft_erp>0.2</soft_erp>
                  <kp>1e+13</kp>
                  <kd>1e+11</kd>
                  <max_vel>-1</max_vel>
                  <min_depth>0</min_depth>
                </ode>
              </contact>
            </surface>
            <laser_retro>0</laser_retro>
            <max_contacts>10</max_contacts>
          </collision>
          <visual name='arm_link_4_geom_visual'>
            <pose>0 -0.01 0.029 0 -0 0</pose>
            <geometry>
              <mesh>
                <uri>model://youbot/meshes/arm/arm4.dae</uri>
              </mesh>
            </geometry>
          </visual>
          <gravity>1</gravity>
          <self_collide>0</self_collide>
          <kinematic>0</kinematic>
          <enable_wind>0</enable_wind>
        </link>
        <link name='arm_link_5'>
          <pose>0.190287 -0.004106 0.367846 -0.085052 0.365926 -0.408445</pose>
          <inertial>
            <pose>0 0.00115 -0.01683 0 -0 0</pose>
            <inertia>
              <ixx>0.00028</ixx>
              <ixy>0</ixy>
              <ixz>0</ixz>
              <iyy>0.000339</iyy>
              <iyz>0</iyz>
              <izz>0.000119</izz>
            </inertia>
            <mass>0.251</mass>
          </inertial>
          <collision name='arm_link_5_geom'>
            <pose>0.003 0 -0.034 0 -0 0</pose>
            <geometry>
              <mesh>
                <uri>model://youbot/meshes/arm/arm5_convex.stl</uri>
              </mesh>
            </geometry>
            <surface>
              <bounce>
                <restitution_coefficient>0</restitution_coefficient>
                <threshold>0</threshold>
              </bounce>
              <contact>
                <ode>
                  <soft_cfm>0</soft_cfm>
                  <soft_erp>0.2</soft_erp>
                  <kp>1e+13</kp>
                  <kd>1e+11</kd>
                  <max_vel>-1</max_vel>
                  <min_depth>0</min_depth>
                </ode>
              </contact>
              <friction>
                <torsional>
                  <ode/>
                </torsional>
                <ode/>
              </friction>
            </surface>
            <laser_retro>0</laser_retro>
            <max_contacts>10</max_contacts>
          </collision>
          <visual name='arm_link_5_geom_visual'>
            <pose>0.003 0 -0.034 0 -0 0</pose>
            <geometry>
              <mesh>
                <uri>model://youbot/meshes/arm/arm5.dae</uri>
              </mesh>
            </geometry>
          </visual>
          <gravity>1</gravity>
          <self_collide>0</self_collide>
          <kinematic>0</kinematic>
          <enable_wind>0</enable_wind>
        </link>
        <link name='gripper_palm_link'>
          <pose>0.190287 -0.004106 0.367846 -0.085052 0.365926 -0.408445</pose>
          <inertial>
            <pose>0 0 0 0 -0 0</pose>
            <inertia>
              <ixx>0.01</ixx>
              <ixy>0</ixy>
              <ixz>0</ixz>
              <iyy>0.01</iyy>
              <iyz>0</iyz>
              <izz>0.01</izz>
            </inertia>
            <mass>0.1</mass>
          </inertial>
          <collision name='gripper_palm_link_geom'>
            <pose>0 0 0 0 -0 0</pose>
            <geometry>
              <mesh>
                <uri>model://youbot/meshes/gripper/palm_convex.stl</uri>
              </mesh>
            </geometry>
            <surface>
              <friction>
                <ode>
                  <mu>0</mu>
                  <mu2>0</mu2>
                  <fdir1>0 0 0</fdir1>
                  <slip1>0</slip1>
                  <slip2>0</slip2>
                </ode>
                <torsional>
                  <ode/>
                </torsional>
              </friction>
              <bounce>
                <restitution_coefficient>0</restitution_coefficient>
                <threshold>0</threshold>
              </bounce>
              <contact>
                <ode>
                  <soft_cfm>0</soft_cfm>
                  <soft_erp>0.2</soft_erp>
                  <kp>1e+13</kp>
                  <kd>1e+11</kd>
                  <max_vel>-1</max_vel>
                  <min_depth>0</min_depth>
                </ode>
              </contact>
            </surface>
            <laser_retro>0</laser_retro>
            <max_contacts>10</max_contacts>
          </collision>
          <visual name='gripper_palm_link_geom_visual'>
            <pose>0 0 0 0 -0 0</pose>
            <geometry>
              <mesh>
                <uri>model://youbot/meshes/gripper/palm.stl</uri>
              </mesh>
            </geometry>
            <material>
              <script>
                <uri>file://media/materials/scripts/gazebo.material</uri>
                <name>Gazebo/Black</name>
              </script>
            </material>
          </visual>
          <gravity>1</gravity>
          <self_collide>1</self_collide>
          <kinematic>0</kinematic>
          <enable_wind>0</enable_wind>
        </link>
        <link name='gripper_finger_link_l'>
          <pose>0.21326 -0.001105 0.408579 0.085052 -0.365926 2.73315</pose>
          <inertial>
            <pose>0 -0.001 0 0 -0 0</pose>
            <inertia>
              <ixx>0.01</ixx>
              <ixy>0</ixy>
              <ixz>0</ixz>
              <iyy>0.01</iyy>
              <iyz>0</iyz>
              <izz>0.01</izz>
            </inertia>
            <mass>0.01</mass>
          </inertial>
          <collision name='gripper_finger_link_l_geom'>
            <pose>0 0 0 0 -0 0</pose>
            <geometry>
              <mesh>
                <uri>model://youbot/meshes/gripper/finger_convex.stl</uri>
              </mesh>
            </geometry>
            <surface>
              <bounce>
                <restitution_coefficient>0</restitution_coefficient>
                <threshold>0</threshold>
              </bounce>
              <contact>
                <ode>
                  <soft_cfm>0</soft_cfm>
                  <soft_erp>0.2</soft_erp>
                  <kp>1e+13</kp>
                  <kd>1e+11</kd>
                  <max_vel>-1</max_vel>
                  <min_depth>0</min_depth>
                </ode>
              </contact>
              <friction>
                <torsional>
                  <ode/>
                </torsional>
                <ode/>
              </friction>
            </surface>
            <laser_retro>0</laser_retro>
            <max_contacts>10</max_contacts>
          </collision>
          <visual name='gripper_finger_link_l_geom_visual'>
            <pose>0 0 0 0 -0 0</pose>
            <geometry>
              <mesh>
                <uri>model://youbot/meshes/gripper/finger.stl</uri>
              </mesh>
            </geometry>
          </visual>
          <gravity>1</gravity>
          <self_collide>0</self_collide>
          <kinematic>0</kinematic>
          <enable_wind>0</enable_wind>
        </link>
        <link name='gripper_finger_link_r'>
          <pose>0.207375 -0.015929 0.409848 -0.085052 0.365926 -0.408445</pose>
          <inertial>
            <pose>0 -0.001 0 0 -0 0</pose>
            <inertia>
              <ixx>0.01</ixx>
              <ixy>0</ixy>
              <ixz>0</ixz>
              <iyy>0.01</iyy>
              <iyz>0</iyz>
              <izz>0.01</izz>
            </inertia>
            <mass>0.01</mass>
          </inertial>
          <collision name='gripper_finger_link_r_geom'>
            <pose>0 0 0 0 -0 0</pose>
            <geometry>
              <mesh>
                <uri>model://youbot/meshes/gripper/finger_convex.stl</uri>
              </mesh>
            </geometry>
            <surface>
              <bounce>
                <restitution_coefficient>0</restitution_coefficient>
                <threshold>0</threshold>
              </bounce>
              <contact>
                <ode>
                  <soft_cfm>0</soft_cfm>
                  <soft_erp>0.2</soft_erp>
                  <kp>1e+13</kp>
                  <kd>1e+11</kd>
                  <max_vel>-1</max_vel>
                  <min_depth>0</min_depth>
                </ode>
              </contact>
              <friction>
                <torsional>
                  <ode/>
                </torsional>
                <ode/>
              </friction>
            </surface>
            <laser_retro>0</laser_retro>
            <max_contacts>10</max_contacts>
          </collision>
          <visual name='gripper_finger_link_r_geom_visual'>
            <pose>0 0 0 0 -0 0</pose>
            <geometry>
              <mesh>
                <uri>model://youbot/meshes/gripper/finger.stl</uri>
              </mesh>
            </geometry>
          </visual>
          <gravity>1</gravity>
          <self_collide>0</self_collide>
          <kinematic>0</kinematic>
          <enable_wind>0</enable_wind>
        </link>
        <link name='base_laser_front_link'>
          <pose>0.3 0 -0.03 0 -0 0</pose>
          <inertial>
            <pose>0 0 0 0 -0 0</pose>
            <inertia>
              <ixx>0.1</ixx>
              <ixy>0</ixy>
              <ixz>0</ixz>
              <iyy>0.1</iyy>
              <iyz>0</iyz>
              <izz>0.1</izz>
            </inertia>
            <mass>0.16</mass>
          </inertial>
          <collision name='base_laser_front_link_geom'>
            <pose>0 0 0 0 -0 0</pose>
            <geometry>
              <mesh>
                <uri>model://hokuyo/meshes/hokuyo_convex.stl</uri>
              </mesh>
            </geometry>
            <surface>
              <bounce>
                <restitution_coefficient>0</restitution_coefficient>
                <threshold>0</threshold>
              </bounce>
              <contact>
                <ode>
                  <soft_cfm>0</soft_cfm>
                  <soft_erp>0.2</soft_erp>
                  <kp>1e+13</kp>
                  <kd>1e+11</kd>
                  <max_vel>-1</max_vel>
                  <min_depth>0</min_depth>
                </ode>
              </contact>
              <friction>
                <torsional>
                  <ode/>
                </torsional>
                <ode/>
              </friction>
            </surface>
            <laser_retro>0</laser_retro>
            <max_contacts>10</max_contacts>
          </collision>
          <visual name='base_laser_front_link_geom_visual'>
            <pose>0 0 0 0 -0 0</pose>
            <geometry>
              <mesh>
                <uri>model://hokuyo/meshes/hokuyo.dae</uri>
              </mesh>
            </geometry>
          </visual>
          <sensor name='base_laser_front' type='ray'>
            <pose>0 0 0 0 -0 0</pose>
            <ray>
              <scan>
                <horizontal>
                  <samples>640</samples>
                  <resolution>1</resolution>
                  <min_angle>-1.57</min_angle>
                  <max_angle>1.57</max_angle>
                </horizontal>
                <vertical>
                  <samples>1</samples>
                  <min_angle>0</min_angle>
                  <max_angle>0</max_angle>
                </vertical>
              </scan>
              <range>
                <min>0.05</min>
                <max>5.6</max>
                <resolution>0.36</resolution>
              </range>
            </ray>
            <always_on>0</always_on>
            <update_rate>10</update_rate>
            <visualize>0</visualize>
          </sensor>
          <gravity>1</gravity>
          <self_collide>0</self_collide>
          <kinematic>0</kinematic>
          <enable_wind>0</enable_wind>
        </link>
        <link name='caster_link_bl'>
          <pose>-0.228 0.158 -0.034 0 -0 0</pose>
          <inertial>
            <pose>0 0 0 0 -0 0</pose>
            <inertia>
              <ixx>0.012412</ixx>
              <ixy>-0.000712</ixy>
              <ixz>0.000503</ixz>
              <iyy>0.015218</iyy>
              <iyz>-4e-06</iyz>
              <izz>0.011764</izz>
            </inertia>
            <mass>0.1</mass>
          </inertial>
          <gravity>1</gravity>
          <self_collide>0</self_collide>
          <kinematic>0</kinematic>
          <enable_wind>0</enable_wind>
        </link>
        <link name='wheel_link_bl'>
          <pose>-0.228 0.158 -0.034 0 -0 0</pose>
          <inertial>
            <pose>0 0 0 0 -0 0</pose>
            <inertia>
              <ixx>0.012412</ixx>
              <ixy>-0.000712</ixy>
              <ixz>0.000503</ixz>
              <iyy>0.015218</iyy>
              <iyz>-4e-06</iyz>
              <izz>0.011764</izz>
            </inertia>
            <mass>0.4</mass>
          </inertial>
          <collision name='wheel_link_bl_geom'>
            <pose>0 0 0 1.5708 -0 0</pose>
            <geometry>
              <cylinder>
                <radius>0.05</radius>
                <length>0.005</length>
              </cylinder>
            </geometry>
            <surface>
              <bounce>
                <restitution_coefficient>0</restitution_coefficient>
                <threshold>0</threshold>
              </bounce>
              <contact>
                <ode>
                  <soft_cfm>0</soft_cfm>
                  <soft_erp>0.2</soft_erp>
                  <kp>1e+13</kp>
                  <kd>1e+11</kd>
                  <max_vel>-1</max_vel>
                  <min_depth>0</min_depth>
                </ode>
              </contact>
              <friction>
                <torsional>
                  <ode/>
                </torsional>
                <ode/>
              </friction>
            </surface>
            <laser_retro>0</laser_retro>
            <max_contacts>10</max_contacts>
          </collision>
          <visual name='wheel_link_bl_geom_visual'>
            <pose>0 0 0 0 -0 0</pose>
            <geometry>
              <mesh>
                <uri>model://youbot/meshes/base/back-left_wheel.dae</uri>
              </mesh>
            </geometry>
            <material>
              <script>
                <uri>model://youbot/materials/scripts/youbot.material</uri>
                <name>youbot/Orange</name>
              </script>
            </material>
          </visual>
          <gravity>1</gravity>
          <self_collide>0</self_collide>
          <kinematic>0</kinematic>
          <enable_wind>0</enable_wind>
        </link>
        <link name='caster_link_br'>
          <pose>-0.228 -0.158 -0.034 0 -0 0</pose>
          <inertial>
            <pose>0 0 0 0 -0 0</pose>
            <inertia>
              <ixx>0.012412</ixx>
              <ixy>-0.000712</ixy>
              <ixz>0.000503</ixz>
              <iyy>0.015218</iyy>
              <iyz>-4e-06</iyz>
              <izz>0.011764</izz>
            </inertia>
            <mass>0.1</mass>
          </inertial>
          <gravity>1</gravity>
          <self_collide>0</self_collide>
          <kinematic>0</kinematic>
          <enable_wind>0</enable_wind>
        </link>
        <link name='wheel_link_br'>
          <pose>-0.228 -0.158 -0.034 0 -0 0</pose>
          <inertial>
            <pose>0 0 0 0 -0 0</pose>
            <inertia>
              <ixx>0.012412</ixx>
              <ixy>-0.000712</ixy>
              <ixz>0.000503</ixz>
              <iyy>0.015218</iyy>
              <iyz>-4e-06</iyz>
              <izz>0.011764</izz>
            </inertia>
            <mass>0.4</mass>
          </inertial>
          <collision name='wheel_link_br_geom'>
            <pose>0 0 0 1.5708 -0 0</pose>
            <geometry>
              <cylinder>
                <radius>0.05</radius>
                <length>0.005</length>
              </cylinder>
            </geometry>
            <surface>
              <bounce>
                <restitution_coefficient>0</restitution_coefficient>
                <threshold>0</threshold>
              </bounce>
              <contact>
                <ode>
                  <soft_cfm>0</soft_cfm>
                  <soft_erp>0.2</soft_erp>
                  <kp>1e+13</kp>
                  <kd>1e+11</kd>
                  <max_vel>-1</max_vel>
                  <min_depth>0</min_depth>
                </ode>
              </contact>
              <friction>
                <torsional>
                  <ode/>
                </torsional>
                <ode/>
              </friction>
            </surface>
            <laser_retro>0</laser_retro>
            <max_contacts>10</max_contacts>
          </collision>
          <visual name='wheel_link_br_geom_visual'>
            <pose>0 0 0 0 -0 0</pose>
            <geometry>
              <mesh>
                <uri>model://youbot/meshes/base/back-right_wheel.dae</uri>
              </mesh>
            </geometry>
            <material>
              <script>
                <uri>model://youbot/materials/scripts/youbot.material</uri>
                <name>youbot/Orange</name>
              </script>
            </material>
          </visual>
          <gravity>1</gravity>
          <self_collide>0</self_collide>
          <kinematic>0</kinematic>
          <enable_wind>0</enable_wind>
        </link>
        <link name='caster_link_fl'>
          <pose>0.228 0.158 -0.034 0 -0 0</pose>
          <inertial>
            <pose>0 0 0 0 -0 0</pose>
            <inertia>
              <ixx>0.012412</ixx>
              <ixy>-0.000712</ixy>
              <ixz>0.000503</ixz>
              <iyy>0.015218</iyy>
              <iyz>-4e-06</iyz>
              <izz>0.011764</izz>
            </inertia>
            <mass>0.1</mass>
          </inertial>
          <gravity>1</gravity>
          <self_collide>0</self_collide>
          <kinematic>0</kinematic>
          <enable_wind>0</enable_wind>
        </link>
        <link name='wheel_link_fl'>
          <pose>0.228 0.158 -0.034 0 -0 0</pose>
          <inertial>
            <pose>0 0 0 0 -0 0</pose>
            <inertia>
              <ixx>0.012412</ixx>
              <ixy>-0.000712</ixy>
              <ixz>0.000503</ixz>
              <iyy>0.015218</iyy>
              <iyz>-4e-06</iyz>
              <izz>0.011764</izz>
            </inertia>
            <mass>0.4</mass>
          </inertial>
          <collision name='wheel_link_fl_geom'>
            <pose>0 0 0 1.5708 -0 0</pose>
            <geometry>
              <cylinder>
                <radius>0.05</radius>
                <length>0.005</length>
              </cylinder>
            </geometry>
            <surface>
              <bounce>
                <restitution_coefficient>0</restitution_coefficient>
                <threshold>0</threshold>
              </bounce>
              <contact>
                <ode>
                  <soft_cfm>0</soft_cfm>
                  <soft_erp>0.2</soft_erp>
                  <kp>1e+13</kp>
                  <kd>1e+11</kd>
                  <max_vel>-1</max_vel>
                  <min_depth>0</min_depth>
                </ode>
              </contact>
              <friction>
                <torsional>
                  <ode/>
                </torsional>
                <ode/>
              </friction>
            </surface>
            <laser_retro>0</laser_retro>
            <max_contacts>10</max_contacts>
          </collision>
          <visual name='wheel_link_fl_geom_visual'>
            <pose>0 0 0 0 -0 0</pose>
            <geometry>
              <mesh>
                <uri>model://youbot/meshes/base/front-left_wheel.dae</uri>
              </mesh>
            </geometry>
            <material>
              <script>
                <uri>model://youbot/materials/scripts/youbot.material</uri>
                <name>youbot/Orange</name>
              </script>
            </material>
          </visual>
          <gravity>1</gravity>
          <self_collide>0</self_collide>
          <kinematic>0</kinematic>
          <enable_wind>0</enable_wind>
        </link>
        <link name='caster_link_fr'>
          <pose>0.228 -0.158 -0.034 0 -0 0</pose>
          <inertial>
            <pose>0 0 0 0 -0 0</pose>
            <inertia>
              <ixx>0.012412</ixx>
              <ixy>-0.000712</ixy>
              <ixz>0.000503</ixz>
              <iyy>0.015218</iyy>
              <iyz>-4e-06</iyz>
              <izz>0.011764</izz>
            </inertia>
            <mass>0.1</mass>
          </inertial>
          <gravity>1</gravity>
          <self_collide>0</self_collide>
          <kinematic>0</kinematic>
          <enable_wind>0</enable_wind>
        </link>
        <link name='wheel_link_fr'>
          <pose>0.228 -0.158 -0.034 0 -0 0</pose>
          <inertial>
            <pose>0 0 0 0 -0 0</pose>
            <inertia>
              <ixx>0.012412</ixx>
              <ixy>-0.000712</ixy>
              <ixz>0.000503</ixz>
              <iyy>0.015218</iyy>
              <iyz>-4e-06</iyz>
              <izz>0.011764</izz>
            </inertia>
            <mass>0.4</mass>
          </inertial>
          <collision name='wheel_link_fr_geom'>
            <pose>0 0 0 1.5708 -0 0</pose>
            <geometry>
              <cylinder>
                <radius>0.05</radius>
                <length>0.005</length>
              </cylinder>
            </geometry>
            <surface>
              <bounce>
                <restitution_coefficient>0</restitution_coefficient>
                <threshold>0</threshold>
              </bounce>
              <contact>
                <ode>
                  <soft_cfm>0</soft_cfm>
                  <soft_erp>0.2</soft_erp>
                  <kp>1e+13</kp>
                  <kd>1e+11</kd>
                  <max_vel>-1</max_vel>
                  <min_depth>0</min_depth>
                </ode>
              </contact>
              <friction>
                <torsional>
                  <ode/>
                </torsional>
                <ode/>
              </friction>
            </surface>
            <laser_retro>0</laser_retro>
            <max_contacts>10</max_contacts>
          </collision>
          <visual name='wheel_link_fr_geom_visual'>
            <pose>0 0 0 0 -0 0</pose>
            <geometry>
              <mesh>
                <uri>model://youbot/meshes/base/front-right_wheel.dae</uri>
              </mesh>
            </geometry>
            <material>
              <script>
                <uri>model://youbot/materials/scripts/youbot.material</uri>
                <name>youbot/Orange</name>
              </script>
            </material>
          </visual>
          <gravity>1</gravity>
          <self_collide>0</self_collide>
          <kinematic>0</kinematic>
          <enable_wind>0</enable_wind>
        </link>
        <link name='plate_link'>
          <pose>-0.159 0 0.046 0 -0 0</pose>
          <inertial>
            <pose>0 0 0 0 -0 0</pose>
            <inertia>
              <ixx>0.01</ixx>
              <ixy>0</ixy>
              <ixz>0</ixz>
              <iyy>0.01</iyy>
              <iyz>0</iyz>
              <izz>0.01</izz>
            </inertia>
            <mass>1</mass>
          </inertial>
          <collision name='plate_link_geom'>
            <pose>0 0 0 0 -0 0</pose>
            <geometry>
              <mesh>
                <uri>model://youbot/meshes/plate/plate_convex.stl</uri>
              </mesh>
            </geometry>
            <surface>
              <bounce>
                <restitution_coefficient>0</restitution_coefficient>
                <threshold>0</threshold>
              </bounce>
              <contact>
                <ode>
                  <soft_cfm>0</soft_cfm>
                  <soft_erp>0.2</soft_erp>
                  <kp>1e+13</kp>
                  <kd>1e+11</kd>
                  <max_vel>-1</max_vel>
                  <min_depth>0</min_depth>
                </ode>
              </contact>
              <friction>
                <torsional>
                  <ode/>
                </torsional>
                <ode/>
              </friction>
            </surface>
            <laser_retro>0</laser_retro>
            <max_contacts>10</max_contacts>
          </collision>
          <visual name='plate_link_geom_visual'>
            <pose>0 0 0 0 -0 0</pose>
            <geometry>
              <mesh>
                <uri>model://youbot/meshes/plate/plate.dae</uri>
              </mesh>
            </geometry>
          </visual>
          <gravity>1</gravity>
          <self_collide>0</self_collide>
          <kinematic>0</kinematic>
          <enable_wind>0</enable_wind>
        </link>
        <joint name='base_footprint_joint' type='revolute'>
          <pose>0 0 0 0 -0 0</pose>
          <parent>base_footprint</parent>
          <child>base_link</child>
          <axis>
            <dynamics>
              <damping>0</damping>
              <friction>0</friction>
              <spring_reference>0</spring_reference>
              <spring_stiffness>0</spring_stiffness>
            </dynamics>
            <limit>
              <lower>0</lower>
              <upper>0</upper>
              <effort>0</effort>
              <velocity>0</velocity>
            </limit>
            <xyz expressed_in='__model__'>0 0 1</xyz>
          </axis>
        </joint>
        <joint name='arm_joint_0' type='revolute'>
          <pose>0 0 0 0 -0 0</pose>
          <parent>base_link</parent>
          <child>arm_link_0</child>
          <axis>
            <dynamics>
              <damping>0</damping>
              <friction>0</friction>
              <spring_reference>0</spring_reference>
              <spring_stiffness>0</spring_stiffness>
            </dynamics>
            <limit>
              <lower>0</lower>
              <upper>0</upper>
              <effort>0</effort>
              <velocity>0</velocity>
            </limit>
            <xyz expressed_in='__model__'>0 0 1</xyz>
          </axis>
        </joint>
        <joint name='arm_joint_1' type='revolute'>
          <pose>0 0 0 0 -0 0</pose>
          <parent>arm_link_0</parent>
          <child>arm_link_1</child>
          <axis>
            <dynamics>
              <damping>1</damping>
              <friction>0</friction>
              <spring_reference>0</spring_reference>
              <spring_stiffness>0</spring_stiffness>
            </dynamics>
            <limit>
              <lower>0</lower>
              <upper>5.89921</upper>
              <effort>9.5</effort>
            </limit>
            <xyz expressed_in='__model__'>0 0 -1</xyz>
          </axis>
        </joint>
        <joint name='arm_joint_2' type='revolute'>
          <pose>0 0 0 0 -0 0</pose>
          <parent>arm_link_1</parent>
          <child>arm_link_2</child>
          <axis>
            <dynamics>
              <damping>1</damping>
              <friction>0</friction>
              <spring_reference>0</spring_reference>
              <spring_stiffness>0</spring_stiffness>
            </dynamics>
            <limit>
              <lower>0</lower>
              <upper>2.70526</upper>
              <effort>9.5</effort>
              <velocity>-1</velocity>
            </limit>
            <xyz expressed_in='__model__'>-0.173648 -0.984808 0</xyz>
          </axis>
        </joint>
        <joint name='arm_joint_3' type='revolute'>
          <pose>0 0 0 0 -0 0</pose>
          <parent>arm_link_2</parent>
          <child>arm_link_3</child>
          <axis>
            <dynamics>
              <damping>1</damping>
              <friction>0</friction>
              <spring_reference>0</spring_reference>
              <spring_stiffness>0</spring_stiffness>
            </dynamics>
            <limit>
              <lower>-5.18363</lower>
              <upper>0</upper>
              <effort>6</effort>
              <velocity>-1</velocity>
            </limit>
            <xyz expressed_in='__model__'>-0.173648 -0.984808 0</xyz>
          </axis>
        </joint>
        <joint name='arm_joint_4' type='revolute'>
          <pose>0 0 0 0 -0 0</pose>
          <parent>arm_link_3</parent>
          <child>arm_link_4</child>
          <axis>
            <dynamics>
              <damping>1</damping>
              <friction>0</friction>
              <spring_reference>0</spring_reference>
              <spring_stiffness>0</spring_stiffness>
            </dynamics>
            <limit>
              <lower>0</lower>
              <upper>3.57793</upper>
              <effort>2</effort>
              <velocity>-1</velocity>
            </limit>
            <xyz expressed_in='__model__'>-0.173648 -0.984808 0</xyz>
          </axis>
        </joint>
        <joint name='arm_joint_5' type='revolute'>
          <pose>0 0 0 0 -0 0</pose>
          <parent>arm_link_4</parent>
          <child>arm_link_5</child>
          <axis>
            <dynamics>
              <damping>1</damping>
              <friction>0</friction>
              <spring_reference>0</spring_reference>
              <spring_stiffness>0</spring_stiffness>
            </dynamics>
            <limit>
              <lower>0</lower>
              <upper>5.84685</upper>
              <effort>1</effort>
              <velocity>-1</velocity>
            </limit>
            <xyz expressed_in='__model__'>-0.360933 0.063642 -0.930418</xyz>
          </axis>
        </joint>
        <joint name='gripper_palm_joint' type='revolute'>
          <pose>0 0 0 0 -0 0</pose>
          <parent>arm_link_5</parent>
          <child>gripper_palm_link</child>
          <axis>
            <dynamics>
              <damping>0</damping>
              <friction>0</friction>
              <spring_reference>0</spring_reference>
              <spring_stiffness>0</spring_stiffness>
            </dynamics>
            <limit>
              <lower>0</lower>
              <upper>0</upper>
              <effort>0</effort>
              <velocity>0</velocity>
            </limit>
            <xyz expressed_in='__model__'>0 0 1</xyz>
          </axis>
        </joint>
        <joint name='gripper_finger_joint_l' type='prismatic'>
          <pose>0 0 0 0 -0 0</pose>
          <parent>gripper_palm_link</parent>
          <child>gripper_finger_link_l</child>
          <axis>
            <dynamics>
              <damping>1</damping>
              <friction>0</friction>
              <spring_reference>0</spring_reference>
              <spring_stiffness>0</spring_stiffness>
            </dynamics>
            <limit>
              <lower>0</lower>
              <upper>0.0115</upper>
              <effort>1</effort>
              <velocity>-1</velocity>
            </limit>
            <xyz expressed_in='__model__'>0.367852 0.926495 -0.079325</xyz>
          </axis>
        </joint>
        <joint name='gripper_finger_joint_r' type='prismatic'>
          <pose>0 0 0 0 -0 0</pose>
          <parent>gripper_palm_link</parent>
          <child>gripper_finger_link_r</child>
          <axis>
            <dynamics>
              <damping>1</damping>
              <friction>0</friction>
              <spring_reference>0</spring_reference>
              <spring_stiffness>0</spring_stiffness>
            </dynamics>
            <limit>
              <lower>0</lower>
              <upper>0.0115</upper>
              <effort>1</effort>
              <velocity>-1</velocity>
            </limit>
            <xyz expressed_in='__model__'>-0.367852 -0.926495 0.079325</xyz>
          </axis>
        </joint>
        <joint name='base_laser_front_hokuyo_urg04_laser_joint' type='revolute'>
          <pose>0 0 0 0 -0 0</pose>
          <parent>base_link</parent>
          <child>base_laser_front_link</child>
          <axis>
            <dynamics>
              <damping>0</damping>
              <friction>0</friction>
              <spring_reference>0</spring_reference>
              <spring_stiffness>0</spring_stiffness>
            </dynamics>
            <limit>
              <lower>0</lower>
              <upper>0</upper>
              <effort>0</effort>
              <velocity>0</velocity>
            </limit>
            <xyz expressed_in='__model__'>0 0 1</xyz>
          </axis>
        </joint>
        <joint name='caster_joint_bl' type='revolute'>
          <pose>0 0 0 0 -0 0</pose>
          <parent>base_link</parent>
          <child>caster_link_bl</child>
          <axis>
            <dynamics>
              <damping>1</damping>
              <friction>0</friction>
              <spring_reference>0</spring_reference>
              <spring_stiffness>0</spring_stiffness>
            </dynamics>
            <limit>
              <effort>1</effort>
              <lower>-1e+16</lower>
              <upper>1e+16</upper>
            </limit>
            <xyz expressed_in='__model__'>0 0 1</xyz>
          </axis>
        </joint>
        <joint name='wheel_joint_bl' type='revolute'>
          <pose>0 0 0 0 -0 0</pose>
          <parent>caster_link_bl</parent>
          <child>wheel_link_bl</child>
          <axis>
            <dynamics>
              <damping>1</damping>
              <friction>0</friction>
              <spring_reference>0</spring_reference>
              <spring_stiffness>0</spring_stiffness>
            </dynamics>
            <limit>
              <effort>1</effort>
              <lower>-1e+16</lower>
              <upper>1e+16</upper>
            </limit>
            <xyz expressed_in='__model__'>0 1 0</xyz>
          </axis>
        </joint>
        <joint name='caster_joint_br' type='revolute'>
          <pose>0 0 0 0 -0 0</pose>
          <parent>base_link</parent>
          <child>caster_link_br</child>
          <axis>
            <dynamics>
              <damping>1</damping>
              <friction>0</friction>
              <spring_reference>0</spring_reference>
              <spring_stiffness>0</spring_stiffness>
            </dynamics>
            <limit>
              <effort>1</effort>
              <lower>-1e+16</lower>
              <upper>1e+16</upper>
            </limit>
            <xyz expressed_in='__model__'>0 0 1</xyz>
          </axis>
        </joint>
        <joint name='wheel_joint_br' type='revolute'>
          <pose>0 0 0 0 -0 0</pose>
          <parent>caster_link_br</parent>
          <child>wheel_link_br</child>
          <axis>
            <dynamics>
              <damping>1</damping>
              <friction>0</friction>
              <spring_reference>0</spring_reference>
              <spring_stiffness>0</spring_stiffness>
            </dynamics>
            <limit>
              <effort>1</effort>
              <lower>-1e+16</lower>
              <upper>1e+16</upper>
            </limit>
            <xyz expressed_in='__model__'>0 1 0</xyz>
          </axis>
        </joint>
        <joint name='caster_joint_fl' type='revolute'>
          <pose>0 0 0 0 -0 0</pose>
          <parent>base_link</parent>
          <child>caster_link_fl</child>
          <axis>
            <dynamics>
              <damping>1</damping>
              <friction>0</friction>
              <spring_reference>0</spring_reference>
              <spring_stiffness>0</spring_stiffness>
            </dynamics>
            <limit>
              <effort>1</effort>
              <lower>-1e+16</lower>
              <upper>1e+16</upper>
            </limit>
            <xyz expressed_in='__model__'>0 0 1</xyz>
          </axis>
        </joint>
        <joint name='wheel_joint_fl' type='revolute'>
          <pose>0 0 0 0 -0 0</pose>
          <parent>caster_link_fl</parent>
          <child>wheel_link_fl</child>
          <axis>
            <dynamics>
              <damping>1</damping>
              <friction>0</friction>
              <spring_reference>0</spring_reference>
              <spring_stiffness>0</spring_stiffness>
            </dynamics>
            <limit>
              <effort>1</effort>
              <lower>-1e+16</lower>
              <upper>1e+16</upper>
            </limit>
            <xyz expressed_in='__model__'>0 1 0</xyz>
          </axis>
        </joint>
        <joint name='caster_joint_fr' type='revolute'>
          <pose>0 0 0 0 -0 0</pose>
          <parent>base_link</parent>
          <child>caster_link_fr</child>
          <axis>
            <dynamics>
              <damping>1</damping>
              <friction>0</friction>
              <spring_reference>0</spring_reference>
              <spring_stiffness>0</spring_stiffness>
            </dynamics>
            <limit>
              <effort>1</effort>
              <lower>-1e+16</lower>
              <upper>1e+16</upper>
            </limit>
            <xyz expressed_in='__model__'>0 0 1</xyz>
          </axis>
        </joint>
        <joint name='wheel_joint_fr' type='revolute'>
          <pose>0 0 0 0 -0 0</pose>
          <parent>caster_link_fr</parent>
          <child>wheel_link_fr</child>
          <axis>
            <dynamics>
              <damping>1</damping>
              <friction>0</friction>
              <spring_reference>0</spring_reference>
              <spring_stiffness>0</spring_stiffness>
            </dynamics>
            <limit>
              <effort>1</effort>
              <lower>-1e+16</lower>
              <upper>1e+16</upper>
            </limit>
            <xyz expressed_in='__model__'>0 1 0</xyz>
          </axis>
        </joint>
        <joint name='plate_joint' type='revolute'>
          <parent>base_link</parent>
          <child>plate_link</child>
          <axis>
            <dynamics>
              <damping>0</damping>
              <friction>0</friction>
              <spring_reference>0</spring_reference>
              <spring_stiffness>0</spring_stiffness>
            </dynamics>
            <limit>
              <lower>0</lower>
              <upper>0</upper>
              <effort>0</effort>
              <velocity>0</velocity>
            </limit>
            <xyz expressed_in='__model__'>0 0 1</xyz>
          </axis>
        </joint>
        <static>0</static>
      </model>
      <model name='zephyr_delta_wing'>
        <pose>0.696621 -0.464605 -0.032115 0 0 -1.43936</pose>
        <link name='wing'>
          <inertial>
            <pose>0 -0.12 0 0 -0 0</pose>
            <mass>1.5</mass>
            <inertia>
              <ixx>0.0831371</ixx>
              <ixy>0</ixy>
              <iyy>0.387382</iyy>
              <ixz>0</ixz>
              <iyz>0</iyz>
              <izz>0.469845</izz>
            </inertia>
          </inertial>
          <visual name='visual'>
            <geometry>
              <mesh>
                <uri>model://zephyr_delta_wing/meshes/wing.dae</uri>
                <submesh>
                  <name>Wing</name>
                  <center>1</center>
                </submesh>
              </mesh>
            </geometry>
          </visual>
          <collision name='body_collision'>
            <geometry>
              <mesh>
                <uri>model://zephyr_delta_wing/meshes/wing.dae</uri>
                <submesh>
                  <name>Wing</name>
                  <center>1</center>
                </submesh>
              </mesh>
            </geometry>
            <surface>
              <contact>
                <ode/>
              </contact>
              <bounce/>
              <friction>
                <torsional>
                  <ode/>
                </torsional>
                <ode/>
              </friction>
            </surface>
            <max_contacts>10</max_contacts>
          </collision>
          <collision name='right_rudder_collision'>
            <pose>-0.76435 0.33918 0.002 -0.03 0 0</pose>
            <geometry>
              <box>
                <size>0.005 0.12993 0.12688</size>
              </box>
            </geometry>
            <surface>
              <contact>
                <ode/>
              </contact>
              <bounce/>
              <friction>
                <torsional>
                  <ode/>
                </torsional>
                <ode/>
              </friction>
            </surface>
            <max_contacts>10</max_contacts>
          </collision>
          <collision name='left_rudder_collision'>
            <pose>0.76435 0.33918 0.002 -0.03 0 0</pose>
            <geometry>
              <box>
                <size>0.005 0.12993 0.12688</size>
              </box>
            </geometry>
            <surface>
              <contact>
                <ode/>
              </contact>
              <bounce/>
              <friction>
                <torsional>
                  <ode/>
                </torsional>
                <ode/>
              </friction>
            </surface>
            <max_contacts>10</max_contacts>
          </collision>
          <sensor name='gps_sensor' type='gps'>
            <pose>0 0 0 0 -0 0</pose>
            <update_rate>10</update_rate>
            <always_on>1</always_on>
            <gps>
              <position_sensing>
                <horizontal>
                  <noise type='gaussian_quantized'>
                    <mean>0</mean>
                    <stddev>1</stddev>
                    <bias_mean>3</bias_mean>
                    <bias_stddev>1</bias_stddev>
                    <precision>0.5</precision>
                  </noise>
                </horizontal>
                <vertical>
                  <noise type='gaussian_quantized'>
                    <mean>0</mean>
                    <stddev>1</stddev>
                    <bias_mean>3</bias_mean>
                    <bias_stddev>1</bias_stddev>
                    <precision>1</precision>
                  </noise>
                </vertical>
              </position_sensing>
              <velocity_sensing>
                <horizontal>
                  <noise type='gaussian_quantized'>
                    <mean>0</mean>
                    <stddev>0.1</stddev>
                    <bias_mean>0.1</bias_mean>
                    <bias_stddev>0.1</bias_stddev>
                    <precision>0.1</precision>
                  </noise>
                </horizontal>
                <vertical>
                  <noise type='gaussian_quantized'>
                    <mean>0</mean>
                    <stddev>0.2</stddev>
                    <bias_mean>0.2</bias_mean>
                    <bias_stddev>0.2</bias_stddev>
                    <precision>0.2</precision>
                  </noise>
                </vertical>
              </velocity_sensing>
            </gps>
          </sensor>
          <self_collide>0</self_collide>
          <enable_wind>0</enable_wind>
          <kinematic>0</kinematic>
        </link>
        <link name='propeller'>
          <pose>0 0.07 0.008 0 1.5707 0</pose>
          <inertial>
            <mass>0.05</mass>
            <inertia>
              <ixx>0.000367571</ixx>
              <ixy>0</ixy>
              <iyy>0.00036985</iyy>
              <ixz>0</ixz>
              <iyz>0</iyz>
              <izz>3.187e-06</izz>
            </inertia>
            <pose>0 0 0 0 -0 0</pose>
          </inertial>
          <visual name='visual'>
            <geometry>
              <mesh>
                <uri>model://zephyr_delta_wing/meshes/wing.dae</uri>
                <submesh>
                  <name>Propeller</name>
                  <center>1</center>
                </submesh>
              </mesh>
            </geometry>
          </visual>
          <collision name='blade1'>
            <pose>0 0 0.074205 0 -0 0.3</pose>
            <geometry>
              <box>
                <size>0.02561 0.00541 0.14841</size>
              </box>
            </geometry>
            <surface>
              <contact>
                <ode/>
              </contact>
              <bounce/>
              <friction>
                <torsional>
                  <ode/>
                </torsional>
                <ode/>
              </friction>
            </surface>
            <max_contacts>10</max_contacts>
          </collision>
          <collision name='blade2'>
            <pose>0 0 -0.074205 0 0 -0.3</pose>
            <geometry>
              <box>
                <size>0.02561 0.00541 0.14841</size>
              </box>
            </geometry>
            <surface>
              <contact>
                <ode/>
              </contact>
              <bounce/>
              <friction>
                <torsional>
                  <ode/>
                </torsional>
                <ode/>
              </friction>
            </surface>
            <max_contacts>10</max_contacts>
          </collision>
          <self_collide>0</self_collide>
          <enable_wind>0</enable_wind>
          <kinematic>0</kinematic>
        </link>
        <link name='flap_left'>
          <pose>0.453 0.239 0.007 0 -0 0</pose>
          <inertial>
            <pose>0 0 0 0 -0 0.324457</pose>
            <mass>0.1</mass>
            <inertia>
              <ixx>0.000102319</ixx>
              <ixy>0</ixy>
              <iyy>0.00334417</iyy>
              <ixz>0</ixz>
              <iyz>0</iyz>
              <izz>0.00344607</izz>
            </inertia>
          </inertial>
          <visual name='visual'>
            <geometry>
              <mesh>
                <uri>model://zephyr_delta_wing/meshes/wing.dae</uri>
                <submesh>
                  <name>Flap_Left</name>
                  <center>1</center>
                </submesh>
              </mesh>
            </geometry>
          </visual>
          <collision name='collision'>
            <pose>-0.01 0.01 0 0 -0 0.324457</pose>
            <geometry>
              <box>
                <size>0.633463 0.110694 0.005</size>
              </box>
            </geometry>
            <surface>
              <contact>
                <ode/>
              </contact>
              <bounce/>
              <friction>
                <torsional>
                  <ode/>
                </torsional>
                <ode/>
              </friction>
            </surface>
            <max_contacts>10</max_contacts>
          </collision>
          <self_collide>0</self_collide>
          <enable_wind>0</enable_wind>
          <kinematic>0</kinematic>
        </link>
        <link name='flap_right'>
          <pose>-0.453 0.239 0.007 0 -0 0</pose>
          <inertial>
            <pose>0 0 0 0 0 -0.324457</pose>
            <mass>0.1</mass>
            <inertia>
              <ixx>0.000102319</ixx>
              <ixy>0</ixy>
              <iyy>0.00334417</iyy>
              <ixz>0</ixz>
              <iyz>0</iyz>
              <izz>0.00344607</izz>
            </inertia>
          </inertial>
          <visual name='visual'>
            <geometry>
              <mesh>
                <uri>model://zephyr_delta_wing/meshes/wing.dae</uri>
                <submesh>
                  <name>Flap_Right</name>
                  <center>1</center>
                </submesh>
              </mesh>
            </geometry>
          </visual>
          <collision name='collision'>
            <pose>0.01 0.01 0 0 0 -0.324457</pose>
            <geometry>
              <box>
                <size>0.633463 0.110694 0.005</size>
              </box>
            </geometry>
            <surface>
              <contact>
                <ode/>
              </contact>
              <bounce/>
              <friction>
                <torsional>
                  <ode/>
                </torsional>
                <ode/>
              </friction>
            </surface>
            <max_contacts>10</max_contacts>
          </collision>
          <self_collide>0</self_collide>
          <enable_wind>0</enable_wind>
          <kinematic>0</kinematic>
        </link>
        <joint name='propeller_joint' type='revolute'>
          <parent>wing</parent>
          <child>propeller</child>
          <axis>
            <xyz>0 -1 0</xyz>
            <dynamics>
              <damping>0.002</damping>
              <spring_reference>0</spring_reference>
              <spring_stiffness>0</spring_stiffness>
            </dynamics>
            <limit>
              <lower>-1e+16</lower>
              <upper>1e+16</upper>
            </limit>
          </axis>
          <physics>
            <ode>
              <implicit_spring_damper>1</implicit_spring_damper>
              <limit>
                <cfm>0</cfm>
                <erp>0.2</erp>
              </limit>
            </ode>
          </physics>
        </joint>
        <joint name='flap_left_joint' type='revolute'>
          <parent>wing</parent>
          <child>flap_left</child>
          <pose>0 -0.04 0 0 -0 0</pose>
          <axis>
            <xyz>1 0.330321 0</xyz>
            <limit>
              <lower>-0.524</lower>
              <upper>0.524</upper>
            </limit>
            <dynamics>
              <damping>0.1</damping>
              <spring_reference>0</spring_reference>
              <spring_stiffness>0</spring_stiffness>
            </dynamics>
          </axis>
          <physics>
            <ode>
              <implicit_spring_damper>1</implicit_spring_damper>
              <limit>
                <cfm>0</cfm>
                <erp>0.2</erp>
              </limit>
            </ode>
          </physics>
        </joint>
        <joint name='flap_right_joint' type='revolute'>
          <parent>wing</parent>
          <child>flap_right</child>
          <pose>0 -0.04 0 0 -0 0</pose>
          <axis>
            <xyz>1 -0.330321 0</xyz>
            <limit>
              <lower>-0.524</lower>
              <upper>0.524</upper>
            </limit>
            <dynamics>
              <damping>0.1</damping>
              <spring_reference>0</spring_reference>
              <spring_stiffness>0</spring_stiffness>
            </dynamics>
          </axis>
          <physics>
            <ode>
              <implicit_spring_damper>1</implicit_spring_damper>
              <limit>
                <cfm>0</cfm>
                <erp>0.2</erp>
              </limit>
            </ode>
          </physics>
        </joint>
        <plugin name='invisible_canard' filename='libLiftDragPlugin.so'>
          <a0>0.13</a0>
          <cla>3.7</cla>
          <cda>0.06417112299</cda>
          <cma>-1.8</cma>
          <alpha_stall>0.3391428111</alpha_stall>
          <cla_stall>-3.85</cla_stall>
          <cda_stall>-0.9233984055</cda_stall>
          <cma_stall>0</cma_stall>
          <cp>0 -0.1 0</cp>
          <area>0.50</area>
          <air_density>1.2041</air_density>
          <forward>0 -1 0</forward>
          <upward>0 0 1</upward>
          <link_name>wing</link_name>
        </plugin>
        <plugin name='left_wing' filename='libLiftDragPlugin.so'>
          <a0>0.15</a0>
          <cla>6.8</cla>
          <cda>0.06417112299</cda>
          <cma>-1.8</cma>
          <alpha_stall>0.6391428111</alpha_stall>
          <cla_stall>-3.85</cla_stall>
          <cda_stall>-0.9233984055</cda_stall>
          <cma_stall>0</cma_stall>
          <cp>0.7 0.20 0</cp>
          <area>0.10</area>
          <air_density>1.2041</air_density>
          <forward>0 -1 0</forward>
          <upward>0 0 1</upward>
          <link_name>wing</link_name>
          <control_joint_name>flap_left_joint</control_joint_name>
          <control_joint_rad_to_cl>-5.0</control_joint_rad_to_cl>
        </plugin>
        <plugin name='right_wing' filename='libLiftDragPlugin.so'>
          <a0>0.15</a0>
          <cla>6.8</cla>
          <cda>0.06417112299</cda>
          <cma>-1.8</cma>
          <alpha_stall>0.6391428111</alpha_stall>
          <cla_stall>-3.85</cla_stall>
          <cda_stall>-0.9233984055</cda_stall>
          <cma_stall>0</cma_stall>
          <cp>-0.7 0.20 0</cp>
          <area>0.10</area>
          <air_density>1.2041</air_density>
          <forward>0 -1 0</forward>
          <upward>0 0 1</upward>
          <link_name>wing</link_name>
          <control_joint_name>flap_right_joint</control_joint_name>
          <control_joint_rad_to_cl>-5.0</control_joint_rad_to_cl>
        </plugin>
        <plugin name='left_rudder' filename='libLiftDragPlugin.so'>
          <a0>0.0</a0>
          <cla>4.752798721</cla>
          <cda>0.6417112299</cda>
          <cma>-1.8</cma>
          <alpha_stall>0.3391428111</alpha_stall>
          <cla_stall>-3.85</cla_stall>
          <cda_stall>-0.9233984055</cda_stall>
          <cma_stall>0</cma_stall>
          <cp>-0.76 0.30 0.025</cp>
          <area>0.12</area>
          <air_density>1.2041</air_density>
          <forward>0 -1 0</forward>
          <upward>1 0 0</upward>
          <link_name>wing</link_name>
        </plugin>
        <plugin name='right_rudder' filename='libLiftDragPlugin.so'>
          <a0>0.0</a0>
          <cla>4.752798721</cla>
          <cda>0.6417112299</cda>
          <cma>-1.8</cma>
          <alpha_stall>0.3391428111</alpha_stall>
          <cla_stall>-3.85</cla_stall>
          <cda_stall>-0.9233984055</cda_stall>
          <cma_stall>0</cma_stall>
          <cp>0.76 0.30 0.025</cp>
          <area>0.12</area>
          <air_density>1.2041</air_density>
          <forward>0 -1 0</forward>
          <upward>1 0 0</upward>
          <link_name>wing</link_name>
        </plugin>
        <plugin name='propeller_blade_1' filename='libLiftDragPlugin.so'>
          <a0>0.30</a0>
          <alpha_stall>1.4</alpha_stall>
          <cla>4.2500</cla>
          <cda>0.10</cda>
          <cma>0.00</cma>
          <cla_stall>-0.025</cla_stall>
          <cda_stall>0.0</cda_stall>
          <cma_stall>0.0</cma_stall>
          <area>0.02</area>
          <air_density>1.2041</air_density>
          <cp>0 0 0.074205</cp>
          <forward>-1 0 0</forward>
          <upward>0 -1 0</upward>
          <link_name>propeller</link_name>
        </plugin>
        <plugin name='propeller_blade_2' filename='libLiftDragPlugin.so'>
          <a0>0.30</a0>
          <alpha_stall>1.4</alpha_stall>
          <cla>4.2500</cla>
          <cda>0.10</cda>
          <cma>0.00</cma>
          <cla_stall>-0.025</cla_stall>
          <cda_stall>0.0</cda_stall>
          <cma_stall>0.0</cma_stall>
          <area>0.02</area>
          <air_density>1.2041</air_density>
          <cp>0 0 -0.074205</cp>
          <forward>1 0 0</forward>
          <upward>0 -1 0</upward>
          <link_name>propeller</link_name>
        </plugin>
      </model>
      <static>0</static>
      <allow_auto_disable>1</allow_auto_disable>
      <pose>1.55493 0.397761 0.057885 0 -0 0</pose>
    </model>
  </world>
</sdf>
